Workbook

Sheet RMP
A2: Project Resource Management Planning
A4: Project name: | B4: Start Date: | C4: End Date: | D4: Time Duration: | E4: Client: | F4: Week:
A5: - | B5: 46024 | C5: 46206 | D5: 27 weeks | E5: - | F5: 46108
E7: Workhours by calendar | F7: NL | G7: 32 | H7: 40 | I7: 40 | J7: 40 | K7: 40 | L7: 40 | M7: 40 | N7: 40 | O7: 40 | P7: 40 | Q7: 32 | R7: 40 | S7: 40 | T7: 32 | U7: 32 | V7: 40 | W7: 40 | X7: 32 | Y7: 40 | Z7: 32 | AA7: 40 | AB7: 32 | AC7: 40 | AD7: 40 | AE7: 40 | AF7: 40 | AG7: 40
G8: =+DATE(YEAR(G10),MONTH(G10),1) -> 46023 | H8: =+DATE(YEAR(H10),MONTH(H10),1) -> 46023 | I8: =+DATE(YEAR(I10),MONTH(I10),1) -> 46023 | J8: =+DATE(YEAR(J10),MONTH(J10),1) -> 46023 | K8: =+DATE(YEAR(K10),MONTH(K10),1) -> 46023 | L8: =+DATE(YEAR(L10),MONTH(L10),1) -> 46054 | M8: =+DATE(YEAR(M10),MONTH(M10),1) -> 46054 | N8: =+DATE(YEAR(N10),MONTH(N10),1) -> 46054 | ... AG8: =+DATE(YEAR(AG10),MONTH(AG10),1) -> 46204 | AJ8: =+DATE(YEAR(AJ10),MONTH(AJ10),1) -> 46023 | AK8: =+DATE(YEAR(AK10),MONTH(AK10),1) -> 46054 | AL8: =+DATE(YEAR(AL10),MONTH(AL10),1) -> 46082 | AM8: =+DATE(YEAR(AM10),MONTH(AM10),1) -> 46113 | AN8: =+DATE(YEAR(AN10),MONTH(AN10),1) -> 46143 | AO8: =+DATE(YEAR(AO10),MONTH(AO10),1) -> 46174 | AP8: =+DATE(YEAR(AP10),MONTH(AP10),1) -> 46204 | AU8: =+DATE(YEAR(AU10),MONTH(AU10),1) -> 46023 | AV8: =+DATE(YEAR(AV10),MONTH(AV10),1) -> 46023 | AW8: =+DATE(YEAR(AW10),MONTH(AW10),1) -> 46023 | AX8: =+DATE(YEAR(AX10),MONTH(AX10),1) -> 46023 | AY8: =+DATE(YEAR(AY10),MONTH(AY10),1) -> 46023 | AZ8: =+DATE(YEAR(AZ10),MONTH(AZ10),1) -> 46054 | BA8: =+DATE(YEAR(BA10),MONTH(BA10),1) -> 46054 | BB8: =+DATE(YEAR(BB10),MONTH(BB10),1) -> 46054 | ... BU8: =+DATE(YEAR(BU10),MONTH(BU10),1) -> 46204 | BX8: =+DATE(YEAR(BX10),MONTH(BX10),1) -> 46023 | BY8: =+DATE(YEAR(BY10),MONTH(BY10),1) -> 46054 | BZ8: =+DATE(YEAR(BZ10),MONTH(BZ10),1) -> 46082 | CA8: =+DATE(YEAR(CA10),MONTH(CA10),1) -> 46113 | CB8: =+DATE(YEAR(CB10),MONTH(CB10),1) -> 46143 | CC8: =+DATE(YEAR(CC10),MONTH(CC10),1) -> 46174 | CD8: =+DATE(YEAR(CD10),MONTH(CD10),1) -> 46204
G9: Weekly hours | AJ9: Monthly hours | AU9: Weekly cost | BX9: Monthly Cost
A10: Baseline/Forecast/Actual | B10: Resource | C10: Position | D10: Discipline | E10: Departament | F10: blank | G10: 46024 | H10: =+G10+7 -> 46031 | I10: =+H10+7 -> 46038 | J10: =+I10+7 -> 46045 | K10: =+J10+7 -> 46052 | L10: =+K10+7 -> 46059 | M10: =+L10+7 -> 46066 | N10: =+M10+7 -> 46073 | O10: =+N10+7 -> 46080 | ... AG10: =+AF10+7 -> 46206 | AH10: Total hours | AI10: blank | AJ10: 46052 | AK10: 46080 | AL10: 46108 | AM10: 46136 | AN10: 46171 | AO10: 46199 | AP10: 46206 | AQ10: Total hours | AR10: blank | AS10: Rate/hr | AT10: blank | AU10: 46024 | AV10: =+AU10+7 -> 46031 | AW10: =+AV10+7 -> 46038 | AX10: =+AW10+7 -> 46045 | AY10: =+AX10+7 -> 46052 | AZ10: =+AY10+7 -> 46059 | BA10: =+AZ10+7 -> 46066 | BB10: =+BA10+7 -> 46073 | BC10: =+BB10+7 -> 46080 | ... BU10: =+BT10+7 -> 46206 | BV10: Total cost | BW10: blank | BX10: 46052 | BY10: 46080 | BZ10: 46108 | CA10: 46136 | CB10: 46171 | CC10: 46199 | CD10: 46206 | CE10: Total cost
A11: Baseline | B11: Lina Maytum | C11: Lead Process Engineer | D11: Process | E11: Engineering | G11: 32 | H11: 40 | I11: 40 | J11: 40 | K11: 40 | L11: 40 | M11: 40 | N11: 40 | O11: 40 | P11: 40 | Q11: 32 | R11: 40 | S11: 40 | T11: 32 | U11: 32 | V11: 40 | W11: 40 | X11: 32 | Y11: 40 | Z11: 32 | AA11: 40 | AB11: 32 | AC11: 40 | AD11: 40 | AE11: 40 | AF11: 40 | AG11: 40 | AH11: =+SUM(G11:AG11) -> 1024 | AJ11: =+SUMIF($G$8:$AG$8,AJ$8,$G11:$AG11) -> 192 | AK11: =+SUMIF($G$8:$AG$8,AK$8,$G11:$AG11) -> 160 | AL11: =+SUMIF($G$8:$AG$8,AL$8,$G11:$AG11) -> 152 | AM11: =+SUMIF($G$8:$AG$8,AM$8,$G11:$AG11) -> 144 | AN11: =+SUMIF($G$8:$AG$8,AN$8,$G11:$AG11) -> 176 | AO11: =+SUMIF($G$8:$AG$8,AO$8,$G11:$AG11) -> 160 | AP11: =+SUMIF($G$8:$AG$8,AP$8,$G11:$AG11) -> 40 | AQ11: =+SUM(AJ11:AP11) -> 1024 | AS11: 100 | AU11: =+IF(G11<>"",$AS11*G11,0) -> 3200 | AV11: =+IF(H11<>"",$AS11*H11,0) -> 4000 | AW11: =+IF(I11<>"",$AS11*I11,0) -> 4000 | AX11: =+IF(J11<>"",$AS11*J11,0) -> 4000 | AY11: =+IF(K11<>"",$AS11*K11,0) -> 4000 | AZ11: =+IF(L11<>"",$AS11*L11,0) -> 4000 | BA11: =+IF(M11<>"",$AS11*M11,0) -> 4000 | BB11: =+IF(N11<>"",$AS11*N11,0) -> 4000 | ... BU11: =+IF(AG11<>"",$AS11*AG11,0) -> 4000 | BV11: =+SUM(AU11:BU11) -> 102400 | BX11: =+SUMIF($AU$8:$BU$8,BX$8,$AU11:$BU11) -> 19200 | BY11: =+SUMIF($AU$8:$BU$8,BY$8,$AU11:$BU11) -> 16000 | BZ11: =+SUMIF($AU$8:$BU$8,BZ$8,$AU11:$BU11) -> 15200 | CA11: =+SUMIF($AU$8:$BU$8,CA$8,$AU11:$BU11) -> 14400 | CB11: =+SUMIF($AU$8:$BU$8,CB$8,$AU11:$BU11) -> 17600 | CC11: =+SUMIF($AU$8:$BU$8,CC$8,$AU11:$BU11) -> 16000 | CD11: =+SUMIF($AU$8:$BU$8,CD$8,$AU11:$BU11) -> 4000 | CE11: =+SUM(BX11:CD11) -> 102400
A12: Baseline | B12: Rutger Claiden | C12: Senior Mechanical Engineer | D12: Mechanical | E12: Engineering | G12: 32 | H12: 40 | I12: 40 | J12: 40 | K12: 40 | L12: 40 | M12: 40 | N12: 40 | O12: 40 | P12: 40 | Q12: 32 | R12: 40 | S12: 40 | T12: 32 | U12: 32 | V12: 40 | W12: 20 | X12: 12 | Y12: 20 | Z12: 12 | AA12: 20 | AB12: 12 | AC12: 20 | AD12: 20 | AE12: 20 | AF12: 20 | AG12: 20 | AH12: =+SUM(G12:AG12) -> 804 | AJ12: =+SUMIF($G$8:$AG$8,AJ$8,$G12:$AG12) -> 192 | AK12: =+SUMIF($G$8:$AG$8,AK$8,$G12:$AG12) -> 160 | AL12: =+SUMIF($G$8:$AG$8,AL$8,$G12:$AG12) -> 152 | AM12: =+SUMIF($G$8:$AG$8,AM$8,$G12:$AG12) -> 124 | AN12: =+SUMIF($G$8:$AG$8,AN$8,$G12:$AG12) -> 76 | AO12: =+SUMIF($G$8:$AG$8,AO$8,$G12:$AG12) -> 80 | AP12: =+SUMIF($G$8:$AG$8,AP$8,$G12:$AG12) -> 20 | AQ12: =+SUM(AJ12:AP12) -> 804 | AS12: 50 | AU12: =+IF(G12<>"",$AS12*G12,0) -> 1600 | AV12: =+IF(H12<>"",$AS12*H12,0) -> 2000 | AW12: =+IF(I12<>"",$AS12*I12,0) -> 2000 | AX12: =+IF(J12<>"",$AS12*J12,0) -> 2000 | AY12: =+IF(K12<>"",$AS12*K12,0) -> 2000 | AZ12: =+IF(L12<>"",$AS12*L12,0) -> 2000 | BA12: =+IF(M12<>"",$AS12*M12,0) -> 2000 | BB12: =+IF(N12<>"",$AS12*N12,0) -> 2000 | ... BU12: =+IF(AG12<>"",$AS12*AG12,0) -> 1000 | BV12: =+SUM(AU12:BU12) -> 40200 | BX12: =+SUMIF($AU$8:$BU$8,BX$8,$AU12:$BU12) -> 9600 | BY12: =+SUMIF($AU$8:$BU$8,BY$8,$AU12:$BU12) -> 8000 | BZ12: =+SUMIF($AU$8:$BU$8,BZ$8,$AU12:$BU12) -> 7600 | CA12: =+SUMIF($AU$8:$BU$8,CA$8,$AU12:$BU12) -> 6200 | CB12: =+SUMIF($AU$8:$BU$8,CB$8,$AU12:$BU12) -> 3800 | CC12: =+SUMIF($AU$8:$BU$8,CC$8,$AU12:$BU12) -> 4000 | CD12: =+SUMIF($AU$8:$BU$8,CD$8,$AU12:$BU12) -> 1000 | CE12: =+SUM(BX12:CD12) -> 40200
A13: Baseline | B13: Mavra Pandie | C13: Instrumentation Engineer | D13: Instrumentation | E13: Engineering | G13: 8 | H13: 16 | I13: 16 | J13: 16 | K13: 16 | L13: 16 | M13: 16 | N13: 16 | O13: 16 | P13: 16 | Q13: 8 | R13: 16 | S13: 16 | T13: 8 | U13: 8 | V13: 16 | W13: 16 | X13: 8 | Y13: 16 | Z13: 8 | AA13: 16 | AB13: 8 | AC13: 16 | AD13: 16 | AE13: 16 | AF13: 0 | AG13: 0 | AH13: =+SUM(G13:AG13) -> 344 | AJ13: =+SUMIF($G$8:$AG$8,AJ$8,$G13:$AG13) -> 72 | AK13: =+SUMIF($G$8:$AG$8,AK$8,$G13:$AG13) -> 64 | AL13: =+SUMIF($G$8:$AG$8,AL$8,$G13:$AG13) -> 56 | AM13: =+SUMIF($G$8:$AG$8,AM$8,$G13:$AG13) -> 48 | AN13: =+SUMIF($G$8:$AG$8,AN$8,$G13:$AG13) -> 56 | AO13: =+SUMIF($G$8:$AG$8,AO$8,$G13:$AG13) -> 48 | AP13: =+SUMIF($G$8:$AG$8,AP$8,$G13:$AG13) -> 0 | AQ13: =+SUM(AJ13:AP13) -> 344 | AS13: 40 | AU13: =+IF(G13<>"",$AS13*G13,0) -> 320 | AV13: =+IF(H13<>"",$AS13*H13,0) -> 640 | AW13: =+IF(I13<>"",$AS13*I13,0) -> 640 | AX13: =+IF(J13<>"",$AS13*J13,0) -> 640 | AY13: =+IF(K13<>"",$AS13*K13,0) -> 640 | AZ13: =+IF(L13<>"",$AS13*L13,0) -> 640 | BA13: =+IF(M13<>"",$AS13*M13,0) -> 640 | BB13: =+IF(N13<>"",$AS13*N13,0) -> 640 | ... BU13: =+IF(AG13<>"",$AS13*AG13,0) -> 0 | BV13: =+SUM(AU13:BU13) -> 13760 | BX13: =+SUMIF($AU$8:$BU$8,BX$8,$AU13:$BU13) -> 2880 | BY13: =+SUMIF($AU$8:$BU$8,BY$8,$AU13:$BU13) -> 2560 | BZ13: =+SUMIF($AU$8:$BU$8,BZ$8,$AU13:$BU13) -> 2240 | CA13: =+SUMIF($AU$8:$BU$8,CA$8,$AU13:$BU13) -> 1920 | CB13: =+SUMIF($AU$8:$BU$8,CB$8,$AU13:$BU13) -> 2240 | CC13: =+SUMIF($AU$8:$BU$8,CC$8,$AU13:$BU13) -> 1920 | CD13: =+SUMIF($AU$8:$BU$8,CD$8,$AU13:$BU13) -> 0 | CE13: =+SUM(BX13:CD13) -> 13760
A14: Baseline | B14: Constancy Van Halle | C14: Senior Piping Engineer | D14: Piping | E14: Engineering | G14: 24 | H14: 32 | I14: 32 | J14: 32 | K14: 32 | L14: 32 | M14: 32 | N14: 32 | O14: 32 | P14: 32 | Q14: 24 | R14: 32 | S14: 32 | T14: 24 | U14: 24 | V14: 32 | W14: 32 | X14: 24 | Y14: 32 | Z14: 24 | AA14: 32 | AB14: 24 | AC14: 16 | AD14: 16 | AE14: 16 | AF14: 16 | AG14: 0 | AH14: =+SUM(G14:AG14) -> 712 | AJ14: =+SUMIF($G$8:$AG$8,AJ$8,$G14:$AG14) -> 152 | AK14: =+SUMIF($G$8:$AG$8,AK$8,$G14:$AG14) -> 128 | AL14: =+SUMIF($G$8:$AG$8,AL$8,$G14:$AG14) -> 120 | AM14: =+SUMIF($G$8:$AG$8,AM$8,$G14:$AG14) -> 112 | AN14: =+SUMIF($G$8:$AG$8,AN$8,$G14:$AG14) -> 136 | AO14: =+SUMIF($G$8:$AG$8,AO$8,$G14:$AG14) -> 64 | AP14: =+SUMIF($G$8:$AG$8,AP$8,$G14:$AG14) -> 0 | AQ14: =+SUM(AJ14:AP14) -> 712 | AS14: 50 | AU14: =+IF(G14<>"",$AS14*G14,0) -> 1200 | AV14: =+IF(H14<>"",$AS14*H14,0) -> 1600 | AW14: =+IF(I14<>"",$AS14*I14,0) -> 1600 | AX14: =+IF(J14<>"",$AS14*J14,0) -> 1600 | AY14: =+IF(K14<>"",$AS14*K14,0) -> 1600 | AZ14: =+IF(L14<>"",$AS14*L14,0) -> 1600 | BA14: =+IF(M14<>"",$AS14*M14,0) -> 1600 | BB14: =+IF(N14<>"",$AS14*N14,0) -> 1600 | ... BU14: =+IF(AG14<>"",$AS14*AG14,0) -> 0 | BV14: =+SUM(AU14:BU14) -> 35600 | BX14: =+SUMIF($AU$8:$BU$8,BX$8,$AU14:$BU14) -> 7600 | BY14: =+SUMIF($AU$8:$BU$8,BY$8,$AU14:$BU14) -> 6400 | BZ14: =+SUMIF($AU$8:$BU$8,BZ$8,$AU14:$BU14) -> 6000 | CA14: =+SUMIF($AU$8:$BU$8,CA$8,$AU14:$BU14) -> 5600 | CB14: =+SUMIF($AU$8:$BU$8,CB$8,$AU14:$BU14) -> 6800 | CC14: =+SUMIF($AU$8:$BU$8,CC$8,$AU14:$BU14) -> 3200 | CD14: =+SUMIF($AU$8:$BU$8,CD$8,$AU14:$BU14) -> 0 | CE14: =+SUM(BX14:CD14) -> 35600
A15: Baseline | B15: Ashli Gaisford | C15: Lead Structural Engineer | D15: Structural | E15: Engineering | G15: 24 | H15: 32 | I15: 32 | J15: 32 | K15: 32 | L15: 32 | M15: 32 | N15: 32 | O15: 32 | P15: 32 | Q15: 24 | R15: 32 | S15: 32 | T15: 24 | U15: 24 | V15: 32 | W15: 32 | X15: 24 | Y15: 32 | Z15: 24 | AA15: 32 | AB15: 24 | AC15: 16 | AD15: 16 | AE15: 16 | AF15: 16 | AG15: 0 | AH15: =+SUM(G15:AG15) -> 712 | AJ15: =+SUMIF($G$8:$AG$8,AJ$8,$G15:$AG15) -> 152 | AK15: =+SUMIF($G$8:$AG$8,AK$8,$G15:$AG15) -> 128 | AL15: =+SUMIF($G$8:$AG$8,AL$8,$G15:$AG15) -> 120 | AM15: =+SUMIF($G$8:$AG$8,AM$8,$G15:$AG15) -> 112 | AN15: =+SUMIF($G$8:$AG$8,AN$8,$G15:$AG15) -> 136 | AO15: =+SUMIF($G$8:$AG$8,AO$8,$G15:$AG15) -> 64 | AP15: =+SUMIF($G$8:$AG$8,AP$8,$G15:$AG15) -> 0 | AQ15: =+SUM(AJ15:AP15) -> 712 | AS15: 100 | AU15: =+IF(G15<>"",$AS15*G15,0) -> 2400 | AV15: =+IF(H15<>"",$AS15*H15,0) -> 3200 | AW15: =+IF(I15<>"",$AS15*I15,0) -> 3200 | AX15: =+IF(J15<>"",$AS15*J15,0) -> 3200 | AY15: =+IF(K15<>"",$AS15*K15,0) -> 3200 | AZ15: =+IF(L15<>"",$AS15*L15,0) -> 3200 | BA15: =+IF(M15<>"",$AS15*M15,0) -> 3200 | BB15: =+IF(N15<>"",$AS15*N15,0) -> 3200 | ... BU15: =+IF(AG15<>"",$AS15*AG15,0) -> 0 | BV15: =+SUM(AU15:BU15) -> 71200 | BX15: =+SUMIF($AU$8:$BU$8,BX$8,$AU15:$BU15) -> 15200 | BY15: =+SUMIF($AU$8:$BU$8,BY$8,$AU15:$BU15) -> 12800 | BZ15: =+SUMIF($AU$8:$BU$8,BZ$8,$AU15:$BU15) -> 12000 | CA15: =+SUMIF($AU$8:$BU$8,CA$8,$AU15:$BU15) -> 11200 | CB15: =+SUMIF($AU$8:$BU$8,CB$8,$AU15:$BU15) -> 13600 | CC15: =+SUMIF($AU$8:$BU$8,CC$8,$AU15:$BU15) -> 6400 | CD15: =+SUMIF($AU$8:$BU$8,CD$8,$AU15:$BU15) -> 0 | CE15: =+SUM(BX15:CD15) -> 71200
A16: Baseline | B16: Minor Betton | C16: Electrical Engineer | D16: Electrical | E16: Engineering | G16: 8 | H16: 16 | I16: 16 | J16: 16 | K16: 16 | L16: 16 | M16: 16 | N16: 16 | O16: 16 | P16: 16 | Q16: 8 | R16: 16 | S16: 16 | T16: 8 | U16: 8 | V16: 16 | W16: 16 | X16: 8 | Y16: 16 | Z16: 8 | AA16: 16 | AB16: 8 | AC16: 16 | AD16: 16 | AE16: 16 | AF16: 16 | AG16: 0 | AH16: =+SUM(G16:AG16) -> 360 | AJ16: =+SUMIF($G$8:$AG$8,AJ$8,$G16:$AG16) -> 72 | AK16: =+SUMIF($G$8:$AG$8,AK$8,$G16:$AG16) -> 64 | AL16: =+SUMIF($G$8:$AG$8,AL$8,$G16:$AG16) -> 56 | AM16: =+SUMIF($G$8:$AG$8,AM$8,$G16:$AG16) -> 48 | AN16: =+SUMIF($G$8:$AG$8,AN$8,$G16:$AG16) -> 56 | AO16: =+SUMIF($G$8:$AG$8,AO$8,$G16:$AG16) -> 64 | AP16: =+SUMIF($G$8:$AG$8,AP$8,$G16:$AG16) -> 0 | AQ16: =+SUM(AJ16:AP16) -> 360 | AS16: 40 | AU16: =+IF(G16<>"",$AS16*G16,0) -> 320 | AV16: =+IF(H16<>"",$AS16*H16,0) -> 640 | AW16: =+IF(I16<>"",$AS16*I16,0) -> 640 | AX16: =+IF(J16<>"",$AS16*J16,0) -> 640 | AY16: =+IF(K16<>"",$AS16*K16,0) -> 640 | AZ16: =+IF(L16<>"",$AS16*L16,0) -> 640 | BA16: =+IF(M16<>"",$AS16*M16,0) -> 640 | BB16: =+IF(N16<>"",$AS16*N16,0) -> 640 | ... BU16: =+IF(AG16<>"",$AS16*AG16,0) -> 0 | BV16: =+SUM(AU16:BU16) -> 14400 | BX16: =+SUMIF($AU$8:$BU$8,BX$8,$AU16:$BU16) -> 2880 | BY16: =+SUMIF($AU$8:$BU$8,BY$8,$AU16:$BU16) -> 2560 | BZ16: =+SUMIF($AU$8:$BU$8,BZ$8,$AU16:$BU16) -> 2240 | CA16: =+SUMIF($AU$8:$BU$8,CA$8,$AU16:$BU16) -> 1920 | CB16: =+SUMIF($AU$8:$BU$8,CB$8,$AU16:$BU16) -> 2240 | CC16: =+SUMIF($AU$8:$BU$8,CC$8,$AU16:$BU16) -> 2560 | CD16: =+SUMIF($AU$8:$BU$8,CD$8,$AU16:$BU16) -> 0 | CE16: =+SUM(BX16:CD16) -> 14400
A17: Baseline | B17: Darren Gellibrand | C17: HSE Engineer | D17: HSE | E17: Engineering | G17: 8 | H17: 16 | I17: 16 | J17: 16 | K17: 16 | L17: 16 | M17: 16 | N17: 16 | O17: 16 | P17: 16 | Q17: 8 | R17: 16 | S17: 16 | T17: 8 | U17: 8 | V17: 16 | W17: 16 | X17: 8 | Y17: 16 | Z17: 8 | AA17: 16 | AB17: 8 | AC17: 16 | AD17: 16 | AE17: 16 | AF17: 16 | AG17: 0 | AH17: =+SUM(G17:AG17) -> 360 | AJ17: =+SUMIF($G$8:$AG$8,AJ$8,$G17:$AG17) -> 72 | AK17: =+SUMIF($G$8:$AG$8,AK$8,$G17:$AG17) -> 64 | AL17: =+SUMIF($G$8:$AG$8,AL$8,$G17:$AG17) -> 56 | AM17: =+SUMIF($G$8:$AG$8,AM$8,$G17:$AG17) -> 48 | AN17: =+SUMIF($G$8:$AG$8,AN$8,$G17:$AG17) -> 56 | AO17: =+SUMIF($G$8:$AG$8,AO$8,$G17:$AG17) -> 64 | AP17: =+SUMIF($G$8:$AG$8,AP$8,$G17:$AG17) -> 0 | AQ17: =+SUM(AJ17:AP17) -> 360 | AS17: 50 | AU17: =+IF(G17<>"",$AS17*G17,0) -> 400 | AV17: =+IF(H17<>"",$AS17*H17,0) -> 800 | AW17: =+IF(I17<>"",$AS17*I17,0) -> 800 | AX17: =+IF(J17<>"",$AS17*J17,0) -> 800 | AY17: =+IF(K17<>"",$AS17*K17,0) -> 800 | AZ17: =+IF(L17<>"",$AS17*L17,0) -> 800 | BA17: =+IF(M17<>"",$AS17*M17,0) -> 800 | BB17: =+IF(N17<>"",$AS17*N17,0) -> 800 | ... BU17: =+IF(AG17<>"",$AS17*AG17,0) -> 0 | BV17: =+SUM(AU17:BU17) -> 18000 | BX17: =+SUMIF($AU$8:$BU$8,BX$8,$AU17:$BU17) -> 3600 | BY17: =+SUMIF($AU$8:$BU$8,BY$8,$AU17:$BU17) -> 3200 | BZ17: =+SUMIF($AU$8:$BU$8,BZ$8,$AU17:$BU17) -> 2800 | CA17: =+SUMIF($AU$8:$BU$8,CA$8,$AU17:$BU17) -> 2400 | CB17: =+SUMIF($AU$8:$BU$8,CB$8,$AU17:$BU17) -> 2800 | CC17: =+SUMIF($AU$8:$BU$8,CC$8,$AU17:$BU17) -> 3200 | CD17: =+SUMIF($AU$8:$BU$8,CD$8,$AU17:$BU17) -> 0 | CE17: =+SUM(BX17:CD17) -> 18000
A18: Baseline | B18: Dulciana Peche | C18: Procurement Specialist | D18: Procurement | E18: Procurement | G18: 32 | H18: 40 | I18: 40 | J18: 40 | K18: 40 | L18: 40 | M18: 40 | N18: 40 | O18: 40 | P18: 40 | Q18: 32 | R18: 40 | S18: 40 | T18: 32 | U18: 32 | V18: 40 | W18: 40 | X18: 32 | Y18: 40 | Z18: 32 | AA18: 40 | AB18: 32 | AC18: 40 | AD18: 40 | AE18: 40 | AF18: 40 | AG18: 40 | AH18: =+SUM(G18:AG18) -> 1024 | AJ18: =+SUMIF($G$8:$AG$8,AJ$8,$G18:$AG18) -> 192 | AK18: =+SUMIF($G$8:$AG$8,AK$8,$G18:$AG18) -> 160 | AL18: =+SUMIF($G$8:$AG$8,AL$8,$G18:$AG18) -> 152 | AM18: =+SUMIF($G$8:$AG$8,AM$8,$G18:$AG18) -> 144 | AN18: =+SUMIF($G$8:$AG$8,AN$8,$G18:$AG18) -> 176 | AO18: =+SUMIF($G$8:$AG$8,AO$8,$G18:$AG18) -> 160 | AP18: =+SUMIF($G$8:$AG$8,AP$8,$G18:$AG18) -> 40 | AQ18: =+SUM(AJ18:AP18) -> 1024 | AS18: 50 | AU18: =+IF(G18<>"",$AS18*G18,0) -> 1600 | AV18: =+IF(H18<>"",$AS18*H18,0) -> 2000 | AW18: =+IF(I18<>"",$AS18*I18,0) -> 2000 | AX18: =+IF(J18<>"",$AS18*J18,0) -> 2000 | AY18: =+IF(K18<>"",$AS18*K18,0) -> 2000 | AZ18: =+IF(L18<>"",$AS18*L18,0) -> 2000 | BA18: =+IF(M18<>"",$AS18*M18,0) -> 2000 | BB18: =+IF(N18<>"",$AS18*N18,0) -> 2000 | ... BU18: =+IF(AG18<>"",$AS18*AG18,0) -> 2000 | BV18: =+SUM(AU18:BU18) -> 51200 | BX18: =+SUMIF($AU$8:$BU$8,BX$8,$AU18:$BU18) -> 9600 | BY18: =+SUMIF($AU$8:$BU$8,BY$8,$AU18:$BU18) -> 8000 | BZ18: =+SUMIF($AU$8:$BU$8,BZ$8,$AU18:$BU18) -> 7600 | CA18: =+SUMIF($AU$8:$BU$8,CA$8,$AU18:$BU18) -> 7200 | CB18: =+SUMIF($AU$8:$BU$8,CB$8,$AU18:$BU18) -> 8800 | CC18: =+SUMIF($AU$8:$BU$8,CC$8,$AU18:$BU18) -> 8000 | CD18: =+SUMIF($AU$8:$BU$8,CD$8,$AU18:$BU18) -> 2000 | CE18: =+SUM(BX18:CD18) -> 51200
A19: Baseline | B19: Alejoa O'Heffernan | C19: Contracts Engineer | D19: Procurement | E19: Procurement | G19: 8 | H19: 16 | I19: 16 | J19: 16 | K19: 16 | L19: 16 | M19: 0 | N19: 0 | O19: 0 | P19: 0 | Q19: 0 | R19: 0 | S19: 0 | T19: 0 | U19: 0 | V19: 0 | W19: 0 | X19: 0 | Y19: 0 | Z19: 0 | AA19: 0 | AB19: 0 | AC19: 0 | AD19: 0 | AE19: 16 | AF19: 16 | AG19: 16 | AH19: =+SUM(G19:AG19) -> 136 | AJ19: =+SUMIF($G$8:$AG$8,AJ$8,$G19:$AG19) -> 72 | AK19: =+SUMIF($G$8:$AG$8,AK$8,$G19:$AG19) -> 16 | AL19: =+SUMIF($G$8:$AG$8,AL$8,$G19:$AG19) -> 0 | AM19: =+SUMIF($G$8:$AG$8,AM$8,$G19:$AG19) -> 0 | AN19: =+SUMIF($G$8:$AG$8,AN$8,$G19:$AG19) -> 0 | AO19: =+SUMIF($G$8:$AG$8,AO$8,$G19:$AG19) -> 32 | AP19: =+SUMIF($G$8:$AG$8,AP$8,$G19:$AG19) -> 16 | AQ19: =+SUM(AJ19:AP19) -> 136 | AS19: 50 | AU19: =+IF(G19<>"",$AS19*G19,0) -> 400 | AV19: =+IF(H19<>"",$AS19*H19,0) -> 800 | AW19: =+IF(I19<>"",$AS19*I19,0) -> 800 | AX19: =+IF(J19<>"",$AS19*J19,0) -> 800 | AY19: =+IF(K19<>"",$AS19*K19,0) -> 800 | AZ19: =+IF(L19<>"",$AS19*L19,0) -> 800 | BA19: =+IF(M19<>"",$AS19*M19,0) -> 0 | BB19: =+IF(N19<>"",$AS19*N19,0) -> 0 | ... BU19: =+IF(AG19<>"",$AS19*AG19,0) -> 800 | BV19: =+SUM(AU19:BU19) -> 6800 | BX19: =+SUMIF($AU$8:$BU$8,BX$8,$AU19:$BU19) -> 3600 | BY19: =+SUMIF($AU$8:$BU$8,BY$8,$AU19:$BU19) -> 800 | BZ19: =+SUMIF($AU$8:$BU$8,BZ$8,$AU19:$BU19) -> 0 | CA19: =+SUMIF($AU$8:$BU$8,CA$8,$AU19:$BU19) -> 0 | CB19: =+SUMIF($AU$8:$BU$8,CB$8,$AU19:$BU19) -> 0 | CC19: =+SUMIF($AU$8:$BU$8,CC$8,$AU19:$BU19) -> 1600 | CD19: =+SUMIF($AU$8:$BU$8,CD$8,$AU19:$BU19) -> 800 | CE19: =+SUM(BX19:CD19) -> 6800
A20: Baseline | B20: Jayme Shufflebotham | C20: Project Controls Lead | D20: Project Controls | E20: Non-engineering | G20: 24 | H20: 32 | I20: 32 | J20: 32 | K20: 32 | L20: 32 | M20: 32 | N20: 32 | O20: 32 | P20: 32 | Q20: 24 | R20: 32 | S20: 32 | T20: 24 | U20: 24 | V20: 32 | W20: 32 | X20: 24 | Y20: 32 | Z20: 24 | AA20: 32 | AB20: 16 | AC20: 24 | AD20: 24 | AE20: 24 | AF20: 24 | AG20: 24 | AH20: =+SUM(G20:AG20) -> 760 | AJ20: =+SUMIF($G$8:$AG$8,AJ$8,$G20:$AG20) -> 152 | AK20: =+SUMIF($G$8:$AG$8,AK$8,$G20:$AG20) -> 128 | AL20: =+SUMIF($G$8:$AG$8,AL$8,$G20:$AG20) -> 120 | AM20: =+SUMIF($G$8:$AG$8,AM$8,$G20:$AG20) -> 112 | AN20: =+SUMIF($G$8:$AG$8,AN$8,$G20:$AG20) -> 128 | AO20: =+SUMIF($G$8:$AG$8,AO$8,$G20:$AG20) -> 96 | AP20: =+SUMIF($G$8:$AG$8,AP$8,$G20:$AG20) -> 24 | AQ20: =+SUM(AJ20:AP20) -> 760 | AS20: 100 | AU20: =+IF(G20<>"",$AS20*G20,0) -> 2400 | AV20: =+IF(H20<>"",$AS20*H20,0) -> 3200 | AW20: =+IF(I20<>"",$AS20*I20,0) -> 3200 | AX20: =+IF(J20<>"",$AS20*J20,0) -> 3200 | AY20: =+IF(K20<>"",$AS20*K20,0) -> 3200 | AZ20: =+IF(L20<>"",$AS20*L20,0) -> 3200 | BA20: =+IF(M20<>"",$AS20*M20,0) -> 3200 | BB20: =+IF(N20<>"",$AS20*N20,0) -> 3200 | ... BU20: =+IF(AG20<>"",$AS20*AG20,0) -> 2400 | BV20: =+SUM(AU20:BU20) -> 76000 | BX20: =+SUMIF($AU$8:$BU$8,BX$8,$AU20:$BU20) -> 15200 | BY20: =+SUMIF($AU$8:$BU$8,BY$8,$AU20:$BU20) -> 12800 | BZ20: =+SUMIF($AU$8:$BU$8,BZ$8,$AU20:$BU20) -> 12000 | CA20: =+SUMIF($AU$8:$BU$8,CA$8,$AU20:$BU20) -> 11200 | CB20: =+SUMIF($AU$8:$BU$8,CB$8,$AU20:$BU20) -> 12800 | CC20: =+SUMIF($AU$8:$BU$8,CC$8,$AU20:$BU20) -> 9600 | CD20: =+SUMIF($AU$8:$BU$8,CD$8,$AU20:$BU20) -> 2400 | CE20: =+SUM(BX20:CD20) -> 76000
A21: Baseline | B21: Aydan Kazimzade | C21: Associate Cost Controller | D21: Project Controls | E21: Non-engineering | G21: 32 | H21: 40 | I21: 40 | J21: 40 | K21: 40 | L21: 40 | M21: 40 | N21: 40 | O21: 40 | P21: 40 | Q21: 32 | R21: 40 | S21: 40 | T21: 32 | U21: 32 | V21: 40 | W21: 40 | X21: 32 | Y21: 40 | Z21: 32 | AA21: 40 | AB21: 32 | AC21: 40 | AD21: 40 | AE21: 40 | AF21: 40 | AG21: 40 | AH21: =+SUM(G21:AG21) -> 1024 | AJ21: =+SUMIF($G$8:$AG$8,AJ$8,$G21:$AG21) -> 192 | AK21: =+SUMIF($G$8:$AG$8,AK$8,$G21:$AG21) -> 160 | AL21: =+SUMIF($G$8:$AG$8,AL$8,$G21:$AG21) -> 152 | AM21: =+SUMIF($G$8:$AG$8,AM$8,$G21:$AG21) -> 144 | AN21: =+SUMIF($G$8:$AG$8,AN$8,$G21:$AG21) -> 176 | AO21: =+SUMIF($G$8:$AG$8,AO$8,$G21:$AG21) -> 160 | AP21: =+SUMIF($G$8:$AG$8,AP$8,$G21:$AG21) -> 40 | AQ21: =+SUM(AJ21:AP21) -> 1024 | AS21: 30 | AU21: =+IF(G21<>"",$AS21*G21,0) -> 960 | AV21: =+IF(H21<>"",$AS21*H21,0) -> 1200 | AW21: =+IF(I21<>"",$AS21*I21,0) -> 1200 | AX21: =+IF(J21<>"",$AS21*J21,0) -> 1200 | AY21: =+IF(K21<>"",$AS21*K21,0) -> 1200 | AZ21: =+IF(L21<>"",$AS21*L21,0) -> 1200 | BA21: =+IF(M21<>"",$AS21*M21,0) -> 1200 | BB21: =+IF(N21<>"",$AS21*N21,0) -> 1200 | ... BU21: =+IF(AG21<>"",$AS21*AG21,0) -> 1200 | BV21: =+SUM(AU21:BU21) -> 30720 | BX21: =+SUMIF($AU$8:$BU$8,BX$8,$AU21:$BU21) -> 5760 | BY21: =+SUMIF($AU$8:$BU$8,BY$8,$AU21:$BU21) -> 4800 | BZ21: =+SUMIF($AU$8:$BU$8,BZ$8,$AU21:$BU21) -> 4560 | CA21: =+SUMIF($AU$8:$BU$8,CA$8,$AU21:$BU21) -> 4320 | CB21: =+SUMIF($AU$8:$BU$8,CB$8,$AU21:$BU21) -> 5280 | CC21: =+SUMIF($AU$8:$BU$8,CC$8,$AU21:$BU21) -> 4800 | CD21: =+SUMIF($AU$8:$BU$8,CD$8,$AU21:$BU21) -> 1200 | CE21: =+SUM(BX21:CD21) -> 30720
A22: Baseline | B22: Abbey McAllister | C22: Project Admin | D22: Information Management | E22: Non-engineering | G22: 32 | H22: 40 | I22: 40 | J22: 40 | K22: 40 | L22: 40 | M22: 40 | N22: 40 | O22: 40 | P22: 40 | Q22: 32 | R22: 40 | S22: 40 | T22: 32 | U22: 32 | V22: 40 | W22: 40 | X22: 32 | Y22: 40 | Z22: 32 | AA22: 40 | AB22: 32 | AC22: 40 | AD22: 40 | AE22: 40 | AF22: 40 | AG22: 40 | AH22: =+SUM(G22:AG22) -> 1024 | AJ22: =+SUMIF($G$8:$AG$8,AJ$8,$G22:$AG22) -> 192 | AK22: =+SUMIF($G$8:$AG$8,AK$8,$G22:$AG22) -> 160 | AL22: =+SUMIF($G$8:$AG$8,AL$8,$G22:$AG22) -> 152 | AM22: =+SUMIF($G$8:$AG$8,AM$8,$G22:$AG22) -> 144 | AN22: =+SUMIF($G$8:$AG$8,AN$8,$G22:$AG22) -> 176 | AO22: =+SUMIF($G$8:$AG$8,AO$8,$G22:$AG22) -> 160 | AP22: =+SUMIF($G$8:$AG$8,AP$8,$G22:$AG22) -> 40 | AQ22: =+SUM(AJ22:AP22) -> 1024 | AS22: 100 | AU22: =+IF(G22<>"",$AS22*G22,0) -> 3200 | AV22: =+IF(H22<>"",$AS22*H22,0) -> 4000 | AW22: =+IF(I22<>"",$AS22*I22,0) -> 4000 | AX22: =+IF(J22<>"",$AS22*J22,0) -> 4000 | AY22: =+IF(K22<>"",$AS22*K22,0) -> 4000 | AZ22: =+IF(L22<>"",$AS22*L22,0) -> 4000 | BA22: =+IF(M22<>"",$AS22*M22,0) -> 4000 | BB22: =+IF(N22<>"",$AS22*N22,0) -> 4000 | ... BU22: =+IF(AG22<>"",$AS22*AG22,0) -> 4000 | BV22: =+SUM(AU22:BU22) -> 102400 | BX22: =+SUMIF($AU$8:$BU$8,BX$8,$AU22:$BU22) -> 19200 | BY22: =+SUMIF($AU$8:$BU$8,BY$8,$AU22:$BU22) -> 16000 | BZ22: =+SUMIF($AU$8:$BU$8,BZ$8,$AU22:$BU22) -> 15200 | CA22: =+SUMIF($AU$8:$BU$8,CA$8,$AU22:$BU22) -> 14400 | CB22: =+SUMIF($AU$8:$BU$8,CB$8,$AU22:$BU22) -> 17600 | CC22: =+SUMIF($AU$8:$BU$8,CC$8,$AU22:$BU22) -> 16000 | CD22: =+SUMIF($AU$8:$BU$8,CD$8,$AU22:$BU22) -> 4000 | CE22: =+SUM(BX22:CD22) -> 102400
F23: Total | G23: =+SUBTOTAL(9,G$11:G$22) -> 264 | H23: =+SUBTOTAL(9,H$11:H$22) -> 360 | I23: =+SUBTOTAL(9,I$11:I$22) -> 360 | J23: =+SUBTOTAL(9,J$11:J$22) -> 360 | K23: =+SUBTOTAL(9,K$11:K$22) -> 360 | L23: =+SUBTOTAL(9,L$11:L$22) -> 360 | M23: =+SUBTOTAL(9,M$11:M$22) -> 344 | N23: =+SUBTOTAL(9,N$11:N$22) -> 344 | ... AH23: =+SUBTOTAL(9,AH$11:AH$22) -> 8284 | AJ23: =+SUBTOTAL(9,AJ$11:AJ$22) -> 1704 | AK23: =+SUBTOTAL(9,AK$11:AK$22) -> 1392 | AL23: =+SUBTOTAL(9,AL$11:AL$22) -> 1288 | AM23: =+SUBTOTAL(9,AM$11:AM$22) -> 1180 | AN23: =+SUBTOTAL(9,AN$11:AN$22) -> 1348 | AO23: =+SUBTOTAL(9,AO$11:AO$22) -> 1152 | AP23: =+SUBTOTAL(9,AP$11:AP$22) -> 220 | AQ23: =+SUBTOTAL(9,AQ$11:AQ$22) -> 8284 | AU23: =+SUBTOTAL(9,AU$11:AU$22) -> 18000 | AV23: =+SUBTOTAL(9,AV$11:AV$22) -> 24080 | AW23: =+SUBTOTAL(9,AW$11:AW$22) -> 24080 | AX23: =+SUBTOTAL(9,AX$11:AX$22) -> 24080 | AY23: =+SUBTOTAL(9,AY$11:AY$22) -> 24080 | AZ23: =+SUBTOTAL(9,AZ$11:AZ$22) -> 24080 | BA23: =+SUBTOTAL(9,BA$11:BA$22) -> 23280 | BB23: =+SUBTOTAL(9,BB$11:BB$22) -> 23280 | ... BV23: =+SUBTOTAL(9,BV$11:BV$22) -> 562680 | BX23: =+SUBTOTAL(9,BX$11:BX$22) -> 114320 | BY23: =+SUBTOTAL(9,BY$11:BY$22) -> 93920 | BZ23: =+SUBTOTAL(9,BZ$11:BZ$22) -> 87440 | CA23: =+SUBTOTAL(9,CA$11:CA$22) -> 80760 | CB23: =+SUBTOTAL(9,CB$11:CB$22) -> 93560 | CC23: =+SUBTOTAL(9,CC$11:CC$22) -> 77280 | CD23: =+SUBTOTAL(9,CD$11:CD$22) -> 15400 | CE23: =+SUBTOTAL(9,CE$11:CE$22) -> 562680
A25: Forecast | B25: Lina Maytum | C25: Lead Process Engineer | D25: Process | E25: Engineering | G25: 32 | H25: 40 | I25: 40 | J25: 40 | K25: 40 | L25: 40 | M25: 40 | N25: 40 | O25: 40 | P25: 40 | Q25: 32 | R25: 40 | S25: 40 | T25: 32 | U25: 32 | V25: 40 | W25: 40 | X25: 32 | Y25: 40 | Z25: 32 | AA25: 40 | AB25: 32 | AC25: 40 | AD25: 40 | AE25: 40 | AF25: 40 | AG25: 40 | AH25: =+SUM(G25:AG25) -> 1024 | AJ25: =+SUMIF($G$8:$AG$8,AJ$8,$G25:$AG25) -> 192 | AK25: =+SUMIF($G$8:$AG$8,AK$8,$G25:$AG25) -> 160 | AL25: =+SUMIF($G$8:$AG$8,AL$8,$G25:$AG25) -> 152 | AM25: =+SUMIF($G$8:$AG$8,AM$8,$G25:$AG25) -> 144 | AN25: =+SUMIF($G$8:$AG$8,AN$8,$G25:$AG25) -> 176 | AO25: =+SUMIF($G$8:$AG$8,AO$8,$G25:$AG25) -> 160 | AP25: =+SUMIF($G$8:$AG$8,AP$8,$G25:$AG25) -> 40 | AQ25: =+SUM(AJ25:AP25) -> 1024 | AS25: 100 | AU25: =+IF(G25<>"",$AS25*G25,0) -> 3200 | AV25: =+IF(H25<>"",$AS25*H25,0) -> 4000 | AW25: =+IF(I25<>"",$AS25*I25,0) -> 4000 | AX25: =+IF(J25<>"",$AS25*J25,0) -> 4000 | AY25: =+IF(K25<>"",$AS25*K25,0) -> 4000 | AZ25: =+IF(L25<>"",$AS25*L25,0) -> 4000 | BA25: =+IF(M25<>"",$AS25*M25,0) -> 4000 | BB25: =+IF(N25<>"",$AS25*N25,0) -> 4000 | ... BU25: =+IF(AG25<>"",$AS25*AG25,0) -> 4000 | BV25: =+SUM(AU25:BU25) -> 102400 | BX25: =+SUMIF($AU$8:$BU$8,BX$8,$AU25:$BU25) -> 19200 | BY25: =+SUMIF($AU$8:$BU$8,BY$8,$AU25:$BU25) -> 16000 | BZ25: =+SUMIF($AU$8:$BU$8,BZ$8,$AU25:$BU25) -> 15200 | CA25: =+SUMIF($AU$8:$BU$8,CA$8,$AU25:$BU25) -> 14400 | CB25: =+SUMIF($AU$8:$BU$8,CB$8,$AU25:$BU25) -> 17600 | CC25: =+SUMIF($AU$8:$BU$8,CC$8,$AU25:$BU25) -> 16000 | CD25: =+SUMIF($AU$8:$BU$8,CD$8,$AU25:$BU25) -> 4000 | CE25: =+SUM(BX25:CD25) -> 102400
A26: Forecast | B26: Rutger Claiden | C26: Senior Mechanical Engineer | D26: Mechanical | E26: Engineering | G26: 32 | H26: 40 | I26: 40 | J26: 40 | K26: 40 | L26: 40 | M26: 40 | N26: 40 | O26: 40 | P26: 40 | Q26: 32 | R26: 40 | S26: 40 | T26: 32 | U26: 32 | V26: 40 | W26: 20 | X26: 12 | Y26: 20 | Z26: 12 | AA26: 20 | AB26: 12 | AC26: 20 | AD26: 20 | AE26: 20 | AF26: 20 | AG26: 20 | AH26: =+SUM(G26:AG26) -> 804 | AJ26: =+SUMIF($G$8:$AG$8,AJ$8,$G26:$AG26) -> 192 | AK26: =+SUMIF($G$8:$AG$8,AK$8,$G26:$AG26) -> 160 | AL26: =+SUMIF($G$8:$AG$8,AL$8,$G26:$AG26) -> 152 | AM26: =+SUMIF($G$8:$AG$8,AM$8,$G26:$AG26) -> 124 | AN26: =+SUMIF($G$8:$AG$8,AN$8,$G26:$AG26) -> 76 | AO26: =+SUMIF($G$8:$AG$8,AO$8,$G26:$AG26) -> 80 | AP26: =+SUMIF($G$8:$AG$8,AP$8,$G26:$AG26) -> 20 | AQ26: =+SUM(AJ26:AP26) -> 804 | AS26: 50 | AU26: =+IF(G26<>"",$AS26*G26,0) -> 1600 | AV26: =+IF(H26<>"",$AS26*H26,0) -> 2000 | AW26: =+IF(I26<>"",$AS26*I26,0) -> 2000 | AX26: =+IF(J26<>"",$AS26*J26,0) -> 2000 | AY26: =+IF(K26<>"",$AS26*K26,0) -> 2000 | AZ26: =+IF(L26<>"",$AS26*L26,0) -> 2000 | BA26: =+IF(M26<>"",$AS26*M26,0) -> 2000 | BB26: =+IF(N26<>"",$AS26*N26,0) -> 2000 | ... BU26: =+IF(AG26<>"",$AS26*AG26,0) -> 1000 | BV26: =+SUM(AU26:BU26) -> 40200 | BX26: =+SUMIF($AU$8:$BU$8,BX$8,$AU26:$BU26) -> 9600 | BY26: =+SUMIF($AU$8:$BU$8,BY$8,$AU26:$BU26) -> 8000 | BZ26: =+SUMIF($AU$8:$BU$8,BZ$8,$AU26:$BU26) -> 7600 | CA26: =+SUMIF($AU$8:$BU$8,CA$8,$AU26:$BU26) -> 6200 | CB26: =+SUMIF($AU$8:$BU$8,CB$8,$AU26:$BU26) -> 3800 | CC26: =+SUMIF($AU$8:$BU$8,CC$8,$AU26:$BU26) -> 4000 | CD26: =+SUMIF($AU$8:$BU$8,CD$8,$AU26:$BU26) -> 1000 | CE26: =+SUM(BX26:CD26) -> 40200
A27: Forecast | B27: Mavra Pandie | C27: Instrumentation Engineer | D27: Instrumentation | E27: Engineering | G27: 8 | H27: 16 | I27: 16 | J27: 16 | K27: 16 | L27: 16 | M27: 16 | N27: 16 | O27: 16 | P27: 16 | Q27: 8 | R27: 16 | S27: 16 | T27: 8 | U27: 8 | V27: 16 | W27: 16 | X27: 8 | Y27: 16 | Z27: 8 | AA27: 16 | AB27: 8 | AC27: 16 | AD27: 16 | AE27: 16 | AF27: 0 | AG27: 0 | AH27: =+SUM(G27:AG27) -> 344 | AJ27: =+SUMIF($G$8:$AG$8,AJ$8,$G27:$AG27) -> 72 | AK27: =+SUMIF($G$8:$AG$8,AK$8,$G27:$AG27) -> 64 | AL27: =+SUMIF($G$8:$AG$8,AL$8,$G27:$AG27) -> 56 | AM27: =+SUMIF($G$8:$AG$8,AM$8,$G27:$AG27) -> 48 | AN27: =+SUMIF($G$8:$AG$8,AN$8,$G27:$AG27) -> 56 | AO27: =+SUMIF($G$8:$AG$8,AO$8,$G27:$AG27) -> 48 | AP27: =+SUMIF($G$8:$AG$8,AP$8,$G27:$AG27) -> 0 | AQ27: =+SUM(AJ27:AP27) -> 344 | AS27: 40 | AU27: =+IF(G27<>"",$AS27*G27,0) -> 320 | AV27: =+IF(H27<>"",$AS27*H27,0) -> 640 | AW27: =+IF(I27<>"",$AS27*I27,0) -> 640 | AX27: =+IF(J27<>"",$AS27*J27,0) -> 640 | AY27: =+IF(K27<>"",$AS27*K27,0) -> 640 | AZ27: =+IF(L27<>"",$AS27*L27,0) -> 640 | BA27: =+IF(M27<>"",$AS27*M27,0) -> 640 | BB27: =+IF(N27<>"",$AS27*N27,0) -> 640 | ... BU27: =+IF(AG27<>"",$AS27*AG27,0) -> 0 | BV27: =+SUM(AU27:BU27) -> 13760 | BX27: =+SUMIF($AU$8:$BU$8,BX$8,$AU27:$BU27) -> 2880 | BY27: =+SUMIF($AU$8:$BU$8,BY$8,$AU27:$BU27) -> 2560 | BZ27: =+SUMIF($AU$8:$BU$8,BZ$8,$AU27:$BU27) -> 2240 | CA27: =+SUMIF($AU$8:$BU$8,CA$8,$AU27:$BU27) -> 1920 | CB27: =+SUMIF($AU$8:$BU$8,CB$8,$AU27:$BU27) -> 2240 | CC27: =+SUMIF($AU$8:$BU$8,CC$8,$AU27:$BU27) -> 1920 | CD27: =+SUMIF($AU$8:$BU$8,CD$8,$AU27:$BU27) -> 0 | CE27: =+SUM(BX27:CD27) -> 13760
A28: Forecast | B28: Constancy Van Halle | C28: Senior Piping Engineer | D28: Piping | E28: Engineering | G28: 24 | H28: 32 | I28: 32 | J28: 32 | K28: 32 | L28: 32 | M28: 32 | N28: 32 | O28: 32 | P28: 32 | Q28: 24 | R28: 32 | S28: 32 | T28: 24 | U28: 24 | V28: 32 | W28: 32 | X28: 24 | Y28: 32 | Z28: 32 | AA28: 32 | AB28: 32 | AC28: 32 | AD28: 16 | AE28: 16 | AF28: 8 | AG28: 8 | AH28: =+SUM(G28:AG28) -> 744 | AJ28: =+SUMIF($G$8:$AG$8,AJ$8,$G28:$AG28) -> 152 | AK28: =+SUMIF($G$8:$AG$8,AK$8,$G28:$AG28) -> 128 | AL28: =+SUMIF($G$8:$AG$8,AL$8,$G28:$AG28) -> 120 | AM28: =+SUMIF($G$8:$AG$8,AM$8,$G28:$AG28) -> 112 | AN28: =+SUMIF($G$8:$AG$8,AN$8,$G28:$AG28) -> 152 | AO28: =+SUMIF($G$8:$AG$8,AO$8,$G28:$AG28) -> 72 | AP28: =+SUMIF($G$8:$AG$8,AP$8,$G28:$AG28) -> 8 | AQ28: =+SUM(AJ28:AP28) -> 744 | AS28: 50 | AU28: =+IF(G28<>"",$AS28*G28,0) -> 1200 | AV28: =+IF(H28<>"",$AS28*H28,0) -> 1600 | AW28: =+IF(I28<>"",$AS28*I28,0) -> 1600 | AX28: =+IF(J28<>"",$AS28*J28,0) -> 1600 | AY28: =+IF(K28<>"",$AS28*K28,0) -> 1600 | AZ28: =+IF(L28<>"",$AS28*L28,0) -> 1600 | BA28: =+IF(M28<>"",$AS28*M28,0) -> 1600 | BB28: =+IF(N28<>"",$AS28*N28,0) -> 1600 | ... BU28: =+IF(AG28<>"",$AS28*AG28,0) -> 400 | BV28: =+SUM(AU28:BU28) -> 37200 | BX28: =+SUMIF($AU$8:$BU$8,BX$8,$AU28:$BU28) -> 7600 | BY28: =+SUMIF($AU$8:$BU$8,BY$8,$AU28:$BU28) -> 6400 | BZ28: =+SUMIF($AU$8:$BU$8,BZ$8,$AU28:$BU28) -> 6000 | CA28: =+SUMIF($AU$8:$BU$8,CA$8,$AU28:$BU28) -> 5600 | CB28: =+SUMIF($AU$8:$BU$8,CB$8,$AU28:$BU28) -> 7600 | CC28: =+SUMIF($AU$8:$BU$8,CC$8,$AU28:$BU28) -> 3600 | CD28: =+SUMIF($AU$8:$BU$8,CD$8,$AU28:$BU28) -> 400 | CE28: =+SUM(BX28:CD28) -> 37200
A29: Forecast | B29: Ashli Gaisford | C29: Lead Structural Engineer | D29: Structural | E29: Engineering | G29: 24 | H29: 32 | I29: 32 | J29: 32 | K29: 32 | L29: 32 | M29: 32 | N29: 32 | O29: 32 | P29: 32 | Q29: 24 | R29: 32 | S29: 32 | T29: 24 | U29: 24 | V29: 32 | W29: 32 | X29: 24 | Y29: 32 | Z29: 24 | AA29: 32 | AB29: 24 | AC29: 16 | AD29: 16 | AE29: 16 | AF29: 8 | AG29: 8 | AH29: =+SUM(G29:AG29) -> 712 | AJ29: =+SUMIF($G$8:$AG$8,AJ$8,$G29:$AG29) -> 152 | AK29: =+SUMIF($G$8:$AG$8,AK$8,$G29:$AG29) -> 128 | AL29: =+SUMIF($G$8:$AG$8,AL$8,$G29:$AG29) -> 120 | AM29: =+SUMIF($G$8:$AG$8,AM$8,$G29:$AG29) -> 112 | AN29: =+SUMIF($G$8:$AG$8,AN$8,$G29:$AG29) -> 136 | AO29: =+SUMIF($G$8:$AG$8,AO$8,$G29:$AG29) -> 56 | AP29: =+SUMIF($G$8:$AG$8,AP$8,$G29:$AG29) -> 8 | AQ29: =+SUM(AJ29:AP29) -> 712 | AS29: 100 | AU29: =+IF(G29<>"",$AS29*G29,0) -> 2400 | AV29: =+IF(H29<>"",$AS29*H29,0) -> 3200 | AW29: =+IF(I29<>"",$AS29*I29,0) -> 3200 | AX29: =+IF(J29<>"",$AS29*J29,0) -> 3200 | AY29: =+IF(K29<>"",$AS29*K29,0) -> 3200 | AZ29: =+IF(L29<>"",$AS29*L29,0) -> 3200 | BA29: =+IF(M29<>"",$AS29*M29,0) -> 3200 | BB29: =+IF(N29<>"",$AS29*N29,0) -> 3200 | ... BU29: =+IF(AG29<>"",$AS29*AG29,0) -> 800 | BV29: =+SUM(AU29:BU29) -> 71200 | BX29: =+SUMIF($AU$8:$BU$8,BX$8,$AU29:$BU29) -> 15200 | BY29: =+SUMIF($AU$8:$BU$8,BY$8,$AU29:$BU29) -> 12800 | BZ29: =+SUMIF($AU$8:$BU$8,BZ$8,$AU29:$BU29) -> 12000 | CA29: =+SUMIF($AU$8:$BU$8,CA$8,$AU29:$BU29) -> 11200 | CB29: =+SUMIF($AU$8:$BU$8,CB$8,$AU29:$BU29) -> 13600 | CC29: =+SUMIF($AU$8:$BU$8,CC$8,$AU29:$BU29) -> 5600 | CD29: =+SUMIF($AU$8:$BU$8,CD$8,$AU29:$BU29) -> 800 | CE29: =+SUM(BX29:CD29) -> 71200
A30: Forecast | B30: Minor Betton | C30: Electrical Engineer | D30: Electrical | E30: Engineering | G30: 8 | H30: 16 | I30: 16 | J30: 16 | K30: 16 | L30: 16 | M30: 16 | N30: 16 | O30: 16 | P30: 16 | Q30: 8 | R30: 16 | S30: 16 | T30: 8 | U30: 8 | V30: 16 | W30: 16 | X30: 8 | Y30: 16 | Z30: 8 | AA30: 16 | AB30: 8 | AC30: 16 | AD30: 16 | AE30: 16 | AF30: 8 | AG30: 8 | AH30: =+SUM(G30:AG30) -> 360 | AJ30: =+SUMIF($G$8:$AG$8,AJ$8,$G30:$AG30) -> 72 | AK30: =+SUMIF($G$8:$AG$8,AK$8,$G30:$AG30) -> 64 | AL30: =+SUMIF($G$8:$AG$8,AL$8,$G30:$AG30) -> 56 | AM30: =+SUMIF($G$8:$AG$8,AM$8,$G30:$AG30) -> 48 | AN30: =+SUMIF($G$8:$AG$8,AN$8,$G30:$AG30) -> 56 | AO30: =+SUMIF($G$8:$AG$8,AO$8,$G30:$AG30) -> 56 | AP30: =+SUMIF($G$8:$AG$8,AP$8,$G30:$AG30) -> 8 | AQ30: =+SUM(AJ30:AP30) -> 360 | AS30: 40 | AU30: =+IF(G30<>"",$AS30*G30,0) -> 320 | AV30: =+IF(H30<>"",$AS30*H30,0) -> 640 | AW30: =+IF(I30<>"",$AS30*I30,0) -> 640 | AX30: =+IF(J30<>"",$AS30*J30,0) -> 640 | AY30: =+IF(K30<>"",$AS30*K30,0) -> 640 | AZ30: =+IF(L30<>"",$AS30*L30,0) -> 640 | BA30: =+IF(M30<>"",$AS30*M30,0) -> 640 | BB30: =+IF(N30<>"",$AS30*N30,0) -> 640 | ... BU30: =+IF(AG30<>"",$AS30*AG30,0) -> 320 | BV30: =+SUM(AU30:BU30) -> 14400 | BX30: =+SUMIF($AU$8:$BU$8,BX$8,$AU30:$BU30) -> 2880 | BY30: =+SUMIF($AU$8:$BU$8,BY$8,$AU30:$BU30) -> 2560 | BZ30: =+SUMIF($AU$8:$BU$8,BZ$8,$AU30:$BU30) -> 2240 | CA30: =+SUMIF($AU$8:$BU$8,CA$8,$AU30:$BU30) -> 1920 | CB30: =+SUMIF($AU$8:$BU$8,CB$8,$AU30:$BU30) -> 2240 | CC30: =+SUMIF($AU$8:$BU$8,CC$8,$AU30:$BU30) -> 2240 | CD30: =+SUMIF($AU$8:$BU$8,CD$8,$AU30:$BU30) -> 320 | CE30: =+SUM(BX30:CD30) -> 14400
A31: Forecast | B31: Darren Gellibrand | C31: HSE Engineer | D31: HSE | E31: Engineering | G31: 8 | H31: 16 | I31: 16 | J31: 16 | K31: 16 | L31: 16 | M31: 16 | N31: 16 | O31: 16 | P31: 16 | Q31: 8 | R31: 16 | S31: 16 | T31: 8 | U31: 8 | V31: 16 | W31: 16 | X31: 8 | Y31: 16 | Z31: 8 | AA31: 16 | AB31: 8 | AC31: 16 | AD31: 16 | AE31: 16 | AF31: 8 | AG31: 8 | AH31: =+SUM(G31:AG31) -> 360 | AJ31: =+SUMIF($G$8:$AG$8,AJ$8,$G31:$AG31) -> 72 | AK31: =+SUMIF($G$8:$AG$8,AK$8,$G31:$AG31) -> 64 | AL31: =+SUMIF($G$8:$AG$8,AL$8,$G31:$AG31) -> 56 | AM31: =+SUMIF($G$8:$AG$8,AM$8,$G31:$AG31) -> 48 | AN31: =+SUMIF($G$8:$AG$8,AN$8,$G31:$AG31) -> 56 | AO31: =+SUMIF($G$8:$AG$8,AO$8,$G31:$AG31) -> 56 | AP31: =+SUMIF($G$8:$AG$8,AP$8,$G31:$AG31) -> 8 | AQ31: =+SUM(AJ31:AP31) -> 360 | AS31: 50 | AU31: =+IF(G31<>"",$AS31*G31,0) -> 400 | AV31: =+IF(H31<>"",$AS31*H31,0) -> 800 | AW31: =+IF(I31<>"",$AS31*I31,0) -> 800 | AX31: =+IF(J31<>"",$AS31*J31,0) -> 800 | AY31: =+IF(K31<>"",$AS31*K31,0) -> 800 | AZ31: =+IF(L31<>"",$AS31*L31,0) -> 800 | BA31: =+IF(M31<>"",$AS31*M31,0) -> 800 | BB31: =+IF(N31<>"",$AS31*N31,0) -> 800 | ... BU31: =+IF(AG31<>"",$AS31*AG31,0) -> 400 | BV31: =+SUM(AU31:BU31) -> 18000 | BX31: =+SUMIF($AU$8:$BU$8,BX$8,$AU31:$BU31) -> 3600 | BY31: =+SUMIF($AU$8:$BU$8,BY$8,$AU31:$BU31) -> 3200 | BZ31: =+SUMIF($AU$8:$BU$8,BZ$8,$AU31:$BU31) -> 2800 | CA31: =+SUMIF($AU$8:$BU$8,CA$8,$AU31:$BU31) -> 2400 | CB31: =+SUMIF($AU$8:$BU$8,CB$8,$AU31:$BU31) -> 2800 | CC31: =+SUMIF($AU$8:$BU$8,CC$8,$AU31:$BU31) -> 2800 | CD31: =+SUMIF($AU$8:$BU$8,CD$8,$AU31:$BU31) -> 400 | CE31: =+SUM(BX31:CD31) -> 18000
A32: Forecast | B32: Dulciana Peche | C32: Procurement Specialist | D32: Procurement | E32: Procurement | G32: 32 | H32: 40 | I32: 40 | J32: 40 | K32: 40 | L32: 40 | M32: 40 | N32: 40 | O32: 40 | P32: 40 | Q32: 32 | R32: 40 | S32: 40 | T32: 32 | U32: 32 | V32: 40 | W32: 40 | X32: 32 | Y32: 40 | Z32: 32 | AA32: 40 | AB32: 32 | AC32: 32 | AD32: 32 | AE32: 32 | AF32: 32 | AG32: 32 | AH32: =+SUM(G32:AG32) -> 984 | AJ32: =+SUMIF($G$8:$AG$8,AJ$8,$G32:$AG32) -> 192 | AK32: =+SUMIF($G$8:$AG$8,AK$8,$G32:$AG32) -> 160 | AL32: =+SUMIF($G$8:$AG$8,AL$8,$G32:$AG32) -> 152 | AM32: =+SUMIF($G$8:$AG$8,AM$8,$G32:$AG32) -> 144 | AN32: =+SUMIF($G$8:$AG$8,AN$8,$G32:$AG32) -> 176 | AO32: =+SUMIF($G$8:$AG$8,AO$8,$G32:$AG32) -> 128 | AP32: =+SUMIF($G$8:$AG$8,AP$8,$G32:$AG32) -> 32 | AQ32: =+SUM(AJ32:AP32) -> 984 | AS32: 50 | AU32: =+IF(G32<>"",$AS32*G32,0) -> 1600 | AV32: =+IF(H32<>"",$AS32*H32,0) -> 2000 | AW32: =+IF(I32<>"",$AS32*I32,0) -> 2000 | AX32: =+IF(J32<>"",$AS32*J32,0) -> 2000 | AY32: =+IF(K32<>"",$AS32*K32,0) -> 2000 | AZ32: =+IF(L32<>"",$AS32*L32,0) -> 2000 | BA32: =+IF(M32<>"",$AS32*M32,0) -> 2000 | BB32: =+IF(N32<>"",$AS32*N32,0) -> 2000 | ... BU32: =+IF(AG32<>"",$AS32*AG32,0) -> 1600 | BV32: =+SUM(AU32:BU32) -> 49200 | BX32: =+SUMIF($AU$8:$BU$8,BX$8,$AU32:$BU32) -> 9600 | BY32: =+SUMIF($AU$8:$BU$8,BY$8,$AU32:$BU32) -> 8000 | BZ32: =+SUMIF($AU$8:$BU$8,BZ$8,$AU32:$BU32) -> 7600 | CA32: =+SUMIF($AU$8:$BU$8,CA$8,$AU32:$BU32) -> 7200 | CB32: =+SUMIF($AU$8:$BU$8,CB$8,$AU32:$BU32) -> 8800 | CC32: =+SUMIF($AU$8:$BU$8,CC$8,$AU32:$BU32) -> 6400 | CD32: =+SUMIF($AU$8:$BU$8,CD$8,$AU32:$BU32) -> 1600 | CE32: =+SUM(BX32:CD32) -> 49200
A33: Forecast | B33: Alejoa O'Heffernan | C33: Contracts Engineer | D33: Procurement | E33: Procurement | G33: 8 | H33: 16 | I33: 16 | J33: 16 | K33: 16 | L33: 16 | M33: 0 | N33: 0 | O33: 0 | P33: 0 | Q33: 0 | R33: 0 | S33: 0 | T33: 0 | U33: 0 | V33: 0 | W33: 0 | X33: 0 | Y33: 0 | Z33: 0 | AA33: 0 | AB33: 0 | AC33: 0 | AD33: 0 | AE33: 16 | AF33: 16 | AG33: 16 | AH33: =+SUM(G33:AG33) -> 136 | AJ33: =+SUMIF($G$8:$AG$8,AJ$8,$G33:$AG33) -> 72 | AK33: =+SUMIF($G$8:$AG$8,AK$8,$G33:$AG33) -> 16 | AL33: =+SUMIF($G$8:$AG$8,AL$8,$G33:$AG33) -> 0 | AM33: =+SUMIF($G$8:$AG$8,AM$8,$G33:$AG33) -> 0 | AN33: =+SUMIF($G$8:$AG$8,AN$8,$G33:$AG33) -> 0 | AO33: =+SUMIF($G$8:$AG$8,AO$8,$G33:$AG33) -> 32 | AP33: =+SUMIF($G$8:$AG$8,AP$8,$G33:$AG33) -> 16 | AQ33: =+SUM(AJ33:AP33) -> 136 | AS33: 50 | AU33: =+IF(G33<>"",$AS33*G33,0) -> 400 | AV33: =+IF(H33<>"",$AS33*H33,0) -> 800 | AW33: =+IF(I33<>"",$AS33*I33,0) -> 800 | AX33: =+IF(J33<>"",$AS33*J33,0) -> 800 | AY33: =+IF(K33<>"",$AS33*K33,0) -> 800 | AZ33: =+IF(L33<>"",$AS33*L33,0) -> 800 | BA33: =+IF(M33<>"",$AS33*M33,0) -> 0 | BB33: =+IF(N33<>"",$AS33*N33,0) -> 0 | ... BU33: =+IF(AG33<>"",$AS33*AG33,0) -> 800 | BV33: =+SUM(AU33:BU33) -> 6800 | BX33: =+SUMIF($AU$8:$BU$8,BX$8,$AU33:$BU33) -> 3600 | BY33: =+SUMIF($AU$8:$BU$8,BY$8,$AU33:$BU33) -> 800 | BZ33: =+SUMIF($AU$8:$BU$8,BZ$8,$AU33:$BU33) -> 0 | CA33: =+SUMIF($AU$8:$BU$8,CA$8,$AU33:$BU33) -> 0 | CB33: =+SUMIF($AU$8:$BU$8,CB$8,$AU33:$BU33) -> 0 | CC33: =+SUMIF($AU$8:$BU$8,CC$8,$AU33:$BU33) -> 1600 | CD33: =+SUMIF($AU$8:$BU$8,CD$8,$AU33:$BU33) -> 800 | CE33: =+SUM(BX33:CD33) -> 6800
A34: Forecast | B34: Jayme Shufflebotham | C34: Project Controls Lead | D34: Project Controls | E34: Non-engineering | G34: 24 | H34: 32 | I34: 32 | J34: 32 | K34: 32 | L34: 32 | M34: 32 | N34: 32 | O34: 32 | P34: 32 | Q34: 24 | R34: 32 | S34: 32 | T34: 24 | U34: 24 | V34: 32 | W34: 32 | X34: 24 | Y34: 32 | Z34: 24 | AA34: 32 | AB34: 16 | AC34: 16 | AD34: 16 | AE34: 16 | AF34: 16 | AG34: 16 | AH34: =+SUM(G34:AG34) -> 720 | AJ34: =+SUMIF($G$8:$AG$8,AJ$8,$G34:$AG34) -> 152 | AK34: =+SUMIF($G$8:$AG$8,AK$8,$G34:$AG34) -> 128 | AL34: =+SUMIF($G$8:$AG$8,AL$8,$G34:$AG34) -> 120 | AM34: =+SUMIF($G$8:$AG$8,AM$8,$G34:$AG34) -> 112 | AN34: =+SUMIF($G$8:$AG$8,AN$8,$G34:$AG34) -> 128 | AO34: =+SUMIF($G$8:$AG$8,AO$8,$G34:$AG34) -> 64 | AP34: =+SUMIF($G$8:$AG$8,AP$8,$G34:$AG34) -> 16 | AQ34: =+SUM(AJ34:AP34) -> 720 | AS34: 100 | AU34: =+IF(G34<>"",$AS34*G34,0) -> 2400 | AV34: =+IF(H34<>"",$AS34*H34,0) -> 3200 | AW34: =+IF(I34<>"",$AS34*I34,0) -> 3200 | AX34: =+IF(J34<>"",$AS34*J34,0) -> 3200 | AY34: =+IF(K34<>"",$AS34*K34,0) -> 3200 | AZ34: =+IF(L34<>"",$AS34*L34,0) -> 3200 | BA34: =+IF(M34<>"",$AS34*M34,0) -> 3200 | BB34: =+IF(N34<>"",$AS34*N34,0) -> 3200 | ... BU34: =+IF(AG34<>"",$AS34*AG34,0) -> 1600 | BV34: =+SUM(AU34:BU34) -> 72000 | BX34: =+SUMIF($AU$8:$BU$8,BX$8,$AU34:$BU34) -> 15200 | BY34: =+SUMIF($AU$8:$BU$8,BY$8,$AU34:$BU34) -> 12800 | BZ34: =+SUMIF($AU$8:$BU$8,BZ$8,$AU34:$BU34) -> 12000 | CA34: =+SUMIF($AU$8:$BU$8,CA$8,$AU34:$BU34) -> 11200 | CB34: =+SUMIF($AU$8:$BU$8,CB$8,$AU34:$BU34) -> 12800 | CC34: =+SUMIF($AU$8:$BU$8,CC$8,$AU34:$BU34) -> 6400 | CD34: =+SUMIF($AU$8:$BU$8,CD$8,$AU34:$BU34) -> 1600 | CE34: =+SUM(BX34:CD34) -> 72000
A35: Forecast | B35: Aydan Kazimzade | C35: Associate Cost Controller | D35: Project Controls | E35: Non-engineering | G35: 32 | H35: 40 | I35: 40 | J35: 40 | K35: 40 | L35: 40 | M35: 40 | N35: 40 | O35: 40 | P35: 40 | Q35: 32 | R35: 40 | S35: 40 | T35: 32 | U35: 32 | V35: 40 | W35: 40 | X35: 32 | Y35: 40 | Z35: 32 | AA35: 40 | AB35: 32 | AC35: 40 | AD35: 40 | AE35: 40 | AF35: 40 | AG35: 40 | AH35: =+SUM(G35:AG35) -> 1024 | AJ35: =+SUMIF($G$8:$AG$8,AJ$8,$G35:$AG35) -> 192 | AK35: =+SUMIF($G$8:$AG$8,AK$8,$G35:$AG35) -> 160 | AL35: =+SUMIF($G$8:$AG$8,AL$8,$G35:$AG35) -> 152 | AM35: =+SUMIF($G$8:$AG$8,AM$8,$G35:$AG35) -> 144 | AN35: =+SUMIF($G$8:$AG$8,AN$8,$G35:$AG35) -> 176 | AO35: =+SUMIF($G$8:$AG$8,AO$8,$G35:$AG35) -> 160 | AP35: =+SUMIF($G$8:$AG$8,AP$8,$G35:$AG35) -> 40 | AQ35: =+SUM(AJ35:AP35) -> 1024 | AS35: 30 | AU35: =+IF(G35<>"",$AS35*G35,0) -> 960 | AV35: =+IF(H35<>"",$AS35*H35,0) -> 1200 | AW35: =+IF(I35<>"",$AS35*I35,0) -> 1200 | AX35: =+IF(J35<>"",$AS35*J35,0) -> 1200 | AY35: =+IF(K35<>"",$AS35*K35,0) -> 1200 | AZ35: =+IF(L35<>"",$AS35*L35,0) -> 1200 | BA35: =+IF(M35<>"",$AS35*M35,0) -> 1200 | BB35: =+IF(N35<>"",$AS35*N35,0) -> 1200 | ... BU35: =+IF(AG35<>"",$AS35*AG35,0) -> 1200 | BV35: =+SUM(AU35:BU35) -> 30720 | BX35: =+SUMIF($AU$8:$BU$8,BX$8,$AU35:$BU35) -> 5760 | BY35: =+SUMIF($AU$8:$BU$8,BY$8,$AU35:$BU35) -> 4800 | BZ35: =+SUMIF($AU$8:$BU$8,BZ$8,$AU35:$BU35) -> 4560 | CA35: =+SUMIF($AU$8:$BU$8,CA$8,$AU35:$BU35) -> 4320 | CB35: =+SUMIF($AU$8:$BU$8,CB$8,$AU35:$BU35) -> 5280 | CC35: =+SUMIF($AU$8:$BU$8,CC$8,$AU35:$BU35) -> 4800 | CD35: =+SUMIF($AU$8:$BU$8,CD$8,$AU35:$BU35) -> 1200 | CE35: =+SUM(BX35:CD35) -> 30720
A36: Forecast | B36: Abbey McAllister | C36: Project Information Manager | D36: Information Management | E36: Non-engineering | G36: 32 | H36: 40 | I36: 40 | J36: 40 | K36: 40 | L36: 40 | M36: 40 | N36: 40 | O36: 40 | P36: 40 | Q36: 32 | R36: 40 | S36: 40 | T36: 32 | U36: 32 | V36: 40 | W36: 40 | X36: 32 | Y36: 40 | Z36: 32 | AA36: 40 | AB36: 32 | AC36: 40 | AD36: 40 | AE36: 40 | AF36: 40 | AG36: 40 | AH36: =+SUM(G36:AG36) -> 1024 | AJ36: =+SUMIF($G$8:$AG$8,AJ$8,$G36:$AG36) -> 192 | AK36: =+SUMIF($G$8:$AG$8,AK$8,$G36:$AG36) -> 160 | AL36: =+SUMIF($G$8:$AG$8,AL$8,$G36:$AG36) -> 152 | AM36: =+SUMIF($G$8:$AG$8,AM$8,$G36:$AG36) -> 144 | AN36: =+SUMIF($G$8:$AG$8,AN$8,$G36:$AG36) -> 176 | AO36: =+SUMIF($G$8:$AG$8,AO$8,$G36:$AG36) -> 160 | AP36: =+SUMIF($G$8:$AG$8,AP$8,$G36:$AG36) -> 40 | AQ36: =+SUM(AJ36:AP36) -> 1024 | AS36: 100 | AU36: =+IF(G36<>"",$AS36*G36,0) -> 3200 | AV36: =+IF(H36<>"",$AS36*H36,0) -> 4000 | AW36: =+IF(I36<>"",$AS36*I36,0) -> 4000 | AX36: =+IF(J36<>"",$AS36*J36,0) -> 4000 | AY36: =+IF(K36<>"",$AS36*K36,0) -> 4000 | AZ36: =+IF(L36<>"",$AS36*L36,0) -> 4000 | BA36: =+IF(M36<>"",$AS36*M36,0) -> 4000 | BB36: =+IF(N36<>"",$AS36*N36,0) -> 4000 | ... BU36: =+IF(AG36<>"",$AS36*AG36,0) -> 4000 | BV36: =+SUM(AU36:BU36) -> 102400 | BX36: =+SUMIF($AU$8:$BU$8,BX$8,$AU36:$BU36) -> 19200 | BY36: =+SUMIF($AU$8:$BU$8,BY$8,$AU36:$BU36) -> 16000 | BZ36: =+SUMIF($AU$8:$BU$8,BZ$8,$AU36:$BU36) -> 15200 | CA36: =+SUMIF($AU$8:$BU$8,CA$8,$AU36:$BU36) -> 14400 | CB36: =+SUMIF($AU$8:$BU$8,CB$8,$AU36:$BU36) -> 17600 | CC36: =+SUMIF($AU$8:$BU$8,CC$8,$AU36:$BU36) -> 16000 | CD36: =+SUMIF($AU$8:$BU$8,CD$8,$AU36:$BU36) -> 4000 | CE36: =+SUM(BX36:CD36) -> 102400
F37: Total | G37: =+SUBTOTAL(9,G$25:G$36) -> 264 | H37: =+SUBTOTAL(9,H$25:H$36) -> 360 | I37: =+SUBTOTAL(9,I$25:I$36) -> 360 | J37: =+SUBTOTAL(9,J$25:J$36) -> 360 | K37: =+SUBTOTAL(9,K$25:K$36) -> 360 | L37: =+SUBTOTAL(9,L$25:L$36) -> 360 | M37: =+SUBTOTAL(9,M$25:M$36) -> 344 | N37: =+SUBTOTAL(9,N$25:N$36) -> 344 | ... AH37: =+SUBTOTAL(9,AH$25:AH$36) -> 8236 | AJ37: =+SUBTOTAL(9,AJ$25:AJ$36) -> 1704 | AK37: =+SUBTOTAL(9,AK$25:AK$36) -> 1392 | AL37: =+SUBTOTAL(9,AL$25:AL$36) -> 1288 | AM37: =+SUBTOTAL(9,AM$25:AM$36) -> 1180 | AN37: =+SUBTOTAL(9,AN$25:AN$36) -> 1364 | AO37: =+SUBTOTAL(9,AO$25:AO$36) -> 1072 | AP37: =+SUBTOTAL(9,AP$25:AP$36) -> 236 | AQ37: =+SUBTOTAL(9,AQ$25:AQ$36) -> 8236 | AU37: =+SUBTOTAL(9,AU$25:AU$36) -> 18000 | AV37: =+SUBTOTAL(9,AV$25:AV$36) -> 24080 | AW37: =+SUBTOTAL(9,AW$25:AW$36) -> 24080 | AX37: =+SUBTOTAL(9,AX$25:AX$36) -> 24080 | AY37: =+SUBTOTAL(9,AY$25:AY$36) -> 24080 | AZ37: =+SUBTOTAL(9,AZ$25:AZ$36) -> 24080 | BA37: =+SUBTOTAL(9,BA$25:BA$36) -> 23280 | BB37: =+SUBTOTAL(9,BB$25:BB$36) -> 23280 | ... BV37: =+SUBTOTAL(9,BV$25:BV$36) -> 558280 | BX37: =+SUBTOTAL(9,BX$25:BX$36) -> 114320 | BY37: =+SUBTOTAL(9,BY$25:BY$36) -> 93920 | BZ37: =+SUBTOTAL(9,BZ$25:BZ$36) -> 87440 | CA37: =+SUBTOTAL(9,CA$25:CA$36) -> 80760 | CB37: =+SUBTOTAL(9,CB$25:CB$36) -> 94360 | CC37: =+SUBTOTAL(9,CC$25:CC$36) -> 71360 | CD37: =+SUBTOTAL(9,CD$25:CD$36) -> 16120 | CE37: =+SUBTOTAL(9,CE$25:CE$36) -> 558280
A39: Actual | B39: =+B25 -> Lina Maytum | C39: =+C25 -> Lead Process Engineer | D39: =+D25 -> Process | E39: =+E25 -> Engineering | G39: 32 | H39: 40 | I39: 40 | J39: 40 | K39: 40 | L39: 40 | M39: 40 | N39: 40 | O39: 40 | P39: 40 | Q39: 32 | R39: 40 | S39: 40 | AH39: =+SUM(G39:AG39) -> 504 | AJ39: =+SUMIF($G$8:$AG$8,AJ$8,$G39:$AG39) -> 192 | AK39: =+SUMIF($G$8:$AG$8,AK$8,$G39:$AG39) -> 160 | AL39: =+SUMIF($G$8:$AG$8,AL$8,$G39:$AG39) -> 152 | AM39: =+SUMIF($G$8:$AG$8,AM$8,$G39:$AG39) -> 0 | AN39: =+SUMIF($G$8:$AG$8,AN$8,$G39:$AG39) -> 0 | AO39: =+SUMIF($G$8:$AG$8,AO$8,$G39:$AG39) -> 0 | AP39: =+SUMIF($G$8:$AG$8,AP$8,$G39:$AG39) -> 0 | AQ39: =+SUM(AJ39:AP39) -> 504 | AS39: =+AS25 -> 100 | AU39: =+IF(G39<>"",$AS39*G39,0) -> 3200 | AV39: =+IF(H39<>"",$AS39*H39,0) -> 4000 | AW39: =+IF(I39<>"",$AS39*I39,0) -> 4000 | AX39: =+IF(J39<>"",$AS39*J39,0) -> 4000 | AY39: =+IF(K39<>"",$AS39*K39,0) -> 4000 | AZ39: =+IF(L39<>"",$AS39*L39,0) -> 4000 | BA39: =+IF(M39<>"",$AS39*M39,0) -> 4000 | BB39: =+IF(N39<>"",$AS39*N39,0) -> 4000 | ... BU39: =+IF(AG39<>"",$AS39*AG39,0) -> 0 | BV39: =+SUM(AU39:BU39) -> 50400 | BX39: =+SUMIF($AU$8:$BU$8,BX$8,$AU39:$BU39) -> 19200 | BY39: =+SUMIF($AU$8:$BU$8,BY$8,$AU39:$BU39) -> 16000 | BZ39: =+SUMIF($AU$8:$BU$8,BZ$8,$AU39:$BU39) -> 15200 | CA39: =+SUMIF($AU$8:$BU$8,CA$8,$AU39:$BU39) -> 0 | CB39: =+SUMIF($AU$8:$BU$8,CB$8,$AU39:$BU39) -> 0 | CC39: =+SUMIF($AU$8:$BU$8,CC$8,$AU39:$BU39) -> 0 | CD39: =+SUMIF($AU$8:$BU$8,CD$8,$AU39:$BU39) -> 0 | CE39: =+SUM(BX39:CD39) -> 50400
A40: Actual | B40: =+B26 -> Rutger Claiden | C40: =+C26 -> Senior Mechanical Engineer | D40: =+D26 -> Mechanical | E40: =+E26 -> Engineering | G40: 32 | H40: 40 | I40: 40 | J40: 40 | K40: 40 | L40: 40 | M40: 40 | N40: 40 | O40: 40 | P40: 40 | Q40: 32 | R40: 40 | S40: 40 | AH40: =+SUM(G40:AG40) -> 504 | AJ40: =+SUMIF($G$8:$AG$8,AJ$8,$G40:$AG40) -> 192 | AK40: =+SUMIF($G$8:$AG$8,AK$8,$G40:$AG40) -> 160 | AL40: =+SUMIF($G$8:$AG$8,AL$8,$G40:$AG40) -> 152 | AM40: =+SUMIF($G$8:$AG$8,AM$8,$G40:$AG40) -> 0 | AN40: =+SUMIF($G$8:$AG$8,AN$8,$G40:$AG40) -> 0 | AO40: =+SUMIF($G$8:$AG$8,AO$8,$G40:$AG40) -> 0 | AP40: =+SUMIF($G$8:$AG$8,AP$8,$G40:$AG40) -> 0 | AQ40: =+SUM(AJ40:AP40) -> 504 | AS40: =+AS26 -> 50 | AU40: =+IF(G40<>"",$AS40*G40,0) -> 1600 | AV40: =+IF(H40<>"",$AS40*H40,0) -> 2000 | AW40: =+IF(I40<>"",$AS40*I40,0) -> 2000 | AX40: =+IF(J40<>"",$AS40*J40,0) -> 2000 | AY40: =+IF(K40<>"",$AS40*K40,0) -> 2000 | AZ40: =+IF(L40<>"",$AS40*L40,0) -> 2000 | BA40: =+IF(M40<>"",$AS40*M40,0) -> 2000 | BB40: =+IF(N40<>"",$AS40*N40,0) -> 2000 | ... BU40: =+IF(AG40<>"",$AS40*AG40,0) -> 0 | BV40: =+SUM(AU40:BU40) -> 25200 | BX40: =+SUMIF($AU$8:$BU$8,BX$8,$AU40:$BU40) -> 9600 | BY40: =+SUMIF($AU$8:$BU$8,BY$8,$AU40:$BU40) -> 8000 | BZ40: =+SUMIF($AU$8:$BU$8,BZ$8,$AU40:$BU40) -> 7600 | CA40: =+SUMIF($AU$8:$BU$8,CA$8,$AU40:$BU40) -> 0 | CB40: =+SUMIF($AU$8:$BU$8,CB$8,$AU40:$BU40) -> 0 | CC40: =+SUMIF($AU$8:$BU$8,CC$8,$AU40:$BU40) -> 0 | CD40: =+SUMIF($AU$8:$BU$8,CD$8,$AU40:$BU40) -> 0 | CE40: =+SUM(BX40:CD40) -> 25200
A41: Actual | B41: =+B27 -> Mavra Pandie | C41: =+C27 -> Instrumentation Engineer | D41: =+D27 -> Instrumentation | E41: =+E27 -> Engineering | G41: 8 | H41: 16 | I41: 16 | J41: 16 | K41: 16 | L41: 16 | M41: 16 | N41: 16 | O41: 16 | P41: 16 | Q41: 8 | R41: 16 | S41: 16 | AH41: =+SUM(G41:AG41) -> 192 | AJ41: =+SUMIF($G$8:$AG$8,AJ$8,$G41:$AG41) -> 72 | AK41: =+SUMIF($G$8:$AG$8,AK$8,$G41:$AG41) -> 64 | AL41: =+SUMIF($G$8:$AG$8,AL$8,$G41:$AG41) -> 56 | AM41: =+SUMIF($G$8:$AG$8,AM$8,$G41:$AG41) -> 0 | AN41: =+SUMIF($G$8:$AG$8,AN$8,$G41:$AG41) -> 0 | AO41: =+SUMIF($G$8:$AG$8,AO$8,$G41:$AG41) -> 0 | AP41: =+SUMIF($G$8:$AG$8,AP$8,$G41:$AG41) -> 0 | AQ41: =+SUM(AJ41:AP41) -> 192 | AS41: =+AS27 -> 40 | AU41: =+IF(G41<>"",$AS41*G41,0) -> 320 | AV41: =+IF(H41<>"",$AS41*H41,0) -> 640 | AW41: =+IF(I41<>"",$AS41*I41,0) -> 640 | AX41: =+IF(J41<>"",$AS41*J41,0) -> 640 | AY41: =+IF(K41<>"",$AS41*K41,0) -> 640 | AZ41: =+IF(L41<>"",$AS41*L41,0) -> 640 | BA41: =+IF(M41<>"",$AS41*M41,0) -> 640 | BB41: =+IF(N41<>"",$AS41*N41,0) -> 640 | ... BU41: =+IF(AG41<>"",$AS41*AG41,0) -> 0 | BV41: =+SUM(AU41:BU41) -> 7680 | BX41: =+SUMIF($AU$8:$BU$8,BX$8,$AU41:$BU41) -> 2880 | BY41: =+SUMIF($AU$8:$BU$8,BY$8,$AU41:$BU41) -> 2560 | BZ41: =+SUMIF($AU$8:$BU$8,BZ$8,$AU41:$BU41) -> 2240 | CA41: =+SUMIF($AU$8:$BU$8,CA$8,$AU41:$BU41) -> 0 | CB41: =+SUMIF($AU$8:$BU$8,CB$8,$AU41:$BU41) -> 0 | CC41: =+SUMIF($AU$8:$BU$8,CC$8,$AU41:$BU41) -> 0 | CD41: =+SUMIF($AU$8:$BU$8,CD$8,$AU41:$BU41) -> 0 | CE41: =+SUM(BX41:CD41) -> 7680
A42: Actual | B42: =+B28 -> Constancy Van Halle | C42: =+C28 -> Senior Piping Engineer | D42: =+D28 -> Piping | E42: =+E28 -> Engineering | G42: 24 | H42: 32 | I42: 32 | J42: 32 | K42: 32 | L42: 32 | M42: 32 | N42: 32 | O42: 32 | P42: 32 | Q42: 24 | R42: 32 | S42: 32 | AH42: =+SUM(G42:AG42) -> 400 | AJ42: =+SUMIF($G$8:$AG$8,AJ$8,$G42:$AG42) -> 152 | AK42: =+SUMIF($G$8:$AG$8,AK$8,$G42:$AG42) -> 128 | AL42: =+SUMIF($G$8:$AG$8,AL$8,$G42:$AG42) -> 120 | AM42: =+SUMIF($G$8:$AG$8,AM$8,$G42:$AG42) -> 0 | AN42: =+SUMIF($G$8:$AG$8,AN$8,$G42:$AG42) -> 0 | AO42: =+SUMIF($G$8:$AG$8,AO$8,$G42:$AG42) -> 0 | AP42: =+SUMIF($G$8:$AG$8,AP$8,$G42:$AG42) -> 0 | AQ42: =+SUM(AJ42:AP42) -> 400 | AS42: =+AS28 -> 50 | AU42: =+IF(G42<>"",$AS42*G42,0) -> 1200 | AV42: =+IF(H42<>"",$AS42*H42,0) -> 1600 | AW42: =+IF(I42<>"",$AS42*I42,0) -> 1600 | AX42: =+IF(J42<>"",$AS42*J42,0) -> 1600 | AY42: =+IF(K42<>"",$AS42*K42,0) -> 1600 | AZ42: =+IF(L42<>"",$AS42*L42,0) -> 1600 | BA42: =+IF(M42<>"",$AS42*M42,0) -> 1600 | BB42: =+IF(N42<>"",$AS42*N42,0) -> 1600 | ... BU42: =+IF(AG42<>"",$AS42*AG42,0) -> 0 | BV42: =+SUM(AU42:BU42) -> 20000 | BX42: =+SUMIF($AU$8:$BU$8,BX$8,$AU42:$BU42) -> 7600 | BY42: =+SUMIF($AU$8:$BU$8,BY$8,$AU42:$BU42) -> 6400 | BZ42: =+SUMIF($AU$8:$BU$8,BZ$8,$AU42:$BU42) -> 6000 | CA42: =+SUMIF($AU$8:$BU$8,CA$8,$AU42:$BU42) -> 0 | CB42: =+SUMIF($AU$8:$BU$8,CB$8,$AU42:$BU42) -> 0 | CC42: =+SUMIF($AU$8:$BU$8,CC$8,$AU42:$BU42) -> 0 | CD42: =+SUMIF($AU$8:$BU$8,CD$8,$AU42:$BU42) -> 0 | CE42: =+SUM(BX42:CD42) -> 20000
A43: Actual | B43: =+B29 -> Ashli Gaisford | C43: =+C29 -> Lead Structural Engineer | D43: =+D29 -> Structural | E43: =+E29 -> Engineering | G43: 24 | H43: 32 | I43: 32 | J43: 32 | K43: 32 | L43: 32 | M43: 32 | N43: 32 | O43: 32 | P43: 32 | Q43: 24 | R43: 32 | S43: 32 | AH43: =+SUM(G43:AG43) -> 400 | AJ43: =+SUMIF($G$8:$AG$8,AJ$8,$G43:$AG43) -> 152 | AK43: =+SUMIF($G$8:$AG$8,AK$8,$G43:$AG43) -> 128 | AL43: =+SUMIF($G$8:$AG$8,AL$8,$G43:$AG43) -> 120 | AM43: =+SUMIF($G$8:$AG$8,AM$8,$G43:$AG43) -> 0 | AN43: =+SUMIF($G$8:$AG$8,AN$8,$G43:$AG43) -> 0 | AO43: =+SUMIF($G$8:$AG$8,AO$8,$G43:$AG43) -> 0 | AP43: =+SUMIF($G$8:$AG$8,AP$8,$G43:$AG43) -> 0 | AQ43: =+SUM(AJ43:AP43) -> 400 | AS43: =+AS29 -> 100 | AU43: =+IF(G43<>"",$AS43*G43,0) -> 2400 | AV43: =+IF(H43<>"",$AS43*H43,0) -> 3200 | AW43: =+IF(I43<>"",$AS43*I43,0) -> 3200 | AX43: =+IF(J43<>"",$AS43*J43,0) -> 3200 | AY43: =+IF(K43<>"",$AS43*K43,0) -> 3200 | AZ43: =+IF(L43<>"",$AS43*L43,0) -> 3200 | BA43: =+IF(M43<>"",$AS43*M43,0) -> 3200 | BB43: =+IF(N43<>"",$AS43*N43,0) -> 3200 | ... BU43: =+IF(AG43<>"",$AS43*AG43,0) -> 0 | BV43: =+SUM(AU43:BU43) -> 40000 | BX43: =+SUMIF($AU$8:$BU$8,BX$8,$AU43:$BU43) -> 15200 | BY43: =+SUMIF($AU$8:$BU$8,BY$8,$AU43:$BU43) -> 12800 | BZ43: =+SUMIF($AU$8:$BU$8,BZ$8,$AU43:$BU43) -> 12000 | CA43: =+SUMIF($AU$8:$BU$8,CA$8,$AU43:$BU43) -> 0 | CB43: =+SUMIF($AU$8:$BU$8,CB$8,$AU43:$BU43) -> 0 | CC43: =+SUMIF($AU$8:$BU$8,CC$8,$AU43:$BU43) -> 0 | CD43: =+SUMIF($AU$8:$BU$8,CD$8,$AU43:$BU43) -> 0 | CE43: =+SUM(BX43:CD43) -> 40000
A44: Actual | B44: =+B30 -> Minor Betton | C44: =+C30 -> Electrical Engineer | D44: =+D30 -> Electrical | E44: =+E30 -> Engineering | G44: 16 | H44: 16 | I44: 16 | J44: 16 | K44: 16 | L44: 16 | M44: 16 | N44: 16 | O44: 16 | P44: 16 | Q44: 8 | R44: 16 | S44: 16 | AH44: =+SUM(G44:AG44) -> 200 | AJ44: =+SUMIF($G$8:$AG$8,AJ$8,$G44:$AG44) -> 80 | AK44: =+SUMIF($G$8:$AG$8,AK$8,$G44:$AG44) -> 64 | AL44: =+SUMIF($G$8:$AG$8,AL$8,$G44:$AG44) -> 56 | AM44: =+SUMIF($G$8:$AG$8,AM$8,$G44:$AG44) -> 0 | AN44: =+SUMIF($G$8:$AG$8,AN$8,$G44:$AG44) -> 0 | AO44: =+SUMIF($G$8:$AG$8,AO$8,$G44:$AG44) -> 0 | AP44: =+SUMIF($G$8:$AG$8,AP$8,$G44:$AG44) -> 0 | AQ44: =+SUM(AJ44:AP44) -> 200 | AS44: =+AS30 -> 40 | AU44: =+IF(G44<>"",$AS44*G44,0) -> 640 | AV44: =+IF(H44<>"",$AS44*H44,0) -> 640 | AW44: =+IF(I44<>"",$AS44*I44,0) -> 640 | AX44: =+IF(J44<>"",$AS44*J44,0) -> 640 | AY44: =+IF(K44<>"",$AS44*K44,0) -> 640 | AZ44: =+IF(L44<>"",$AS44*L44,0) -> 640 | BA44: =+IF(M44<>"",$AS44*M44,0) -> 640 | BB44: =+IF(N44<>"",$AS44*N44,0) -> 640 | ... BU44: =+IF(AG44<>"",$AS44*AG44,0) -> 0 | BV44: =+SUM(AU44:BU44) -> 8000 | BX44: =+SUMIF($AU$8:$BU$8,BX$8,$AU44:$BU44) -> 3200 | BY44: =+SUMIF($AU$8:$BU$8,BY$8,$AU44:$BU44) -> 2560 | BZ44: =+SUMIF($AU$8:$BU$8,BZ$8,$AU44:$BU44) -> 2240 | CA44: =+SUMIF($AU$8:$BU$8,CA$8,$AU44:$BU44) -> 0 | CB44: =+SUMIF($AU$8:$BU$8,CB$8,$AU44:$BU44) -> 0 | CC44: =+SUMIF($AU$8:$BU$8,CC$8,$AU44:$BU44) -> 0 | CD44: =+SUMIF($AU$8:$BU$8,CD$8,$AU44:$BU44) -> 0 | CE44: =+SUM(BX44:CD44) -> 8000
A45: Actual | B45: =+B31 -> Darren Gellibrand | C45: =+C31 -> HSE Engineer | D45: =+D31 -> HSE | E45: =+E31 -> Engineering | G45: 16 | H45: 16 | I45: 16 | J45: 16 | K45: 16 | L45: 16 | M45: 16 | N45: 16 | O45: 16 | P45: 16 | Q45: 8 | R45: 16 | S45: 8 | AH45: =+SUM(G45:AG45) -> 192 | AJ45: =+SUMIF($G$8:$AG$8,AJ$8,$G45:$AG45) -> 80 | AK45: =+SUMIF($G$8:$AG$8,AK$8,$G45:$AG45) -> 64 | AL45: =+SUMIF($G$8:$AG$8,AL$8,$G45:$AG45) -> 48 | AM45: =+SUMIF($G$8:$AG$8,AM$8,$G45:$AG45) -> 0 | AN45: =+SUMIF($G$8:$AG$8,AN$8,$G45:$AG45) -> 0 | AO45: =+SUMIF($G$8:$AG$8,AO$8,$G45:$AG45) -> 0 | AP45: =+SUMIF($G$8:$AG$8,AP$8,$G45:$AG45) -> 0 | AQ45: =+SUM(AJ45:AP45) -> 192 | AS45: =+AS31 -> 50 | AU45: =+IF(G45<>"",$AS45*G45,0) -> 800 | AV45: =+IF(H45<>"",$AS45*H45,0) -> 800 | AW45: =+IF(I45<>"",$AS45*I45,0) -> 800 | AX45: =+IF(J45<>"",$AS45*J45,0) -> 800 | AY45: =+IF(K45<>"",$AS45*K45,0) -> 800 | AZ45: =+IF(L45<>"",$AS45*L45,0) -> 800 | BA45: =+IF(M45<>"",$AS45*M45,0) -> 800 | BB45: =+IF(N45<>"",$AS45*N45,0) -> 800 | ... BU45: =+IF(AG45<>"",$AS45*AG45,0) -> 0 | BV45: =+SUM(AU45:BU45) -> 9600 | BX45: =+SUMIF($AU$8:$BU$8,BX$8,$AU45:$BU45) -> 4000 | BY45: =+SUMIF($AU$8:$BU$8,BY$8,$AU45:$BU45) -> 3200 | BZ45: =+SUMIF($AU$8:$BU$8,BZ$8,$AU45:$BU45) -> 2400 | CA45: =+SUMIF($AU$8:$BU$8,CA$8,$AU45:$BU45) -> 0 | CB45: =+SUMIF($AU$8:$BU$8,CB$8,$AU45:$BU45) -> 0 | CC45: =+SUMIF($AU$8:$BU$8,CC$8,$AU45:$BU45) -> 0 | CD45: =+SUMIF($AU$8:$BU$8,CD$8,$AU45:$BU45) -> 0 | CE45: =+SUM(BX45:CD45) -> 9600
...

Sheet Monthly Cost Report
B2: Project Monthly Cost Report | N2: Cut-off: | O2: 46108
B4: Description | D4: Budget | F4: Period Actual | H4: Actual to Date | J4: Forecast at Completion | L4: Forecast to Go | N4: Budget Variance
D5: Hours | E5: Cost | F5: Hours | G5: Cost | H5: Hours | I5: Cost | J5: Hours | K5: Cost | L5: Hours | M5: Cost | N5: Hours | O5: Cost
B7: Discipline | C7: Process | D7: {=+SUMPRODUCT((RMP!$A$11:$A$51="Baseline")*(RMP!$D$11:$D$51='Monthly Cost Report'!$C7)*(RMP!$AH$11:$AH$51))} -> 1024 | E7: {=+SUMPRODUCT((RMP!$A$11:$A$51="Baseline")*(RMP!$D$11:$D$51='Monthly Cost Report'!$C7)*(RMP!$BV$11:$BV$51))} -> 102400 | F7: {=+SUMPRODUCT(("Actual"=RMP!$A$11:$A$51)*('Monthly Cost Report'!$C7=RMP!$D$11:$D$51)*(RMP!$AJ$10:$AP$10='Monthly Cost Report'!$O$2)*RMP!$AJ$11:$AP$51)} -> 152 | G7: {=+SUMPRODUCT(("Actual"=RMP!$A$11:$A$51)*('Monthly Cost Report'!$C7=RMP!$D$11:$D$51)*(RMP!$BX$10:$CD$10='Monthly Cost Report'!$O$2)*RMP!$BX$11:$CD$51)} -> 15200 | H7: {=+SUMPRODUCT(("Actual"=RMP!$A$11:$A$51)*('Monthly Cost Report'!$C7=RMP!$D$11:$D$51)*(RMP!$AJ$10:$AP$10<='Monthly Cost Report'!$O$2)*RMP!$AJ$11:$AP$51)} -> 504 | I7: {=+SUMPRODUCT(("Actual"=RMP!$A$11:$A$51)*('Monthly Cost Report'!$C7=RMP!$D$11:$D$51)*(RMP!$BX$10:$CD$10<='Monthly Cost Report'!$O$2)*RMP!$BX$11:$CD$51)} -> 50400 | J7: {=+$H7+(SUMPRODUCT(("Forecast"=RMP!$A$11:$A$51)*('Monthly Cost Report'!$C7=RMP!$D$11:$D$51)*(RMP!$AJ$10:$AP$10>'Monthly Cost Report'!$O$2)*RMP!$AJ$11:$AP$51))} -> 1024 | K7: {=+$I7+(SUMPRODUCT(("Forecast"=RMP!$A$11:$A$51)*('Monthly Cost Report'!$C7=RMP!$D$11:$D$51)*(RMP!$BX$10:$CD$10>'Monthly Cost Report'!$O$2)*RMP!$BX$11:$CD$51))} -> 102400 | L7: =+J7-H7 -> 520 | M7: =+K7-I7 -> 52000 | N7: =+J7-D7 -> 0 | O7: =+K7-E7 -> 0
C8: Mechanical | D8: {=+SUMPRODUCT((RMP!$A$11:$A$51="Baseline")*(RMP!$D$11:$D$51='Monthly Cost Report'!$C8)*(RMP!$AH$11:$AH$51))} -> 804 | E8: {=+SUMPRODUCT((RMP!$A$11:$A$51="Baseline")*(RMP!$D$11:$D$51='Monthly Cost Report'!$C8)*(RMP!$BV$11:$BV$51))} -> 40200 | F8: {=+SUMPRODUCT(("Actual"=RMP!$A$11:$A$51)*('Monthly Cost Report'!$C8=RMP!$D$11:$D$51)*(RMP!$AJ$10:$AP$10='Monthly Cost Report'!$O$2)*RMP!$AJ$11:$AP$51)} -> 152 | G8: {=+SUMPRODUCT(("Actual"=RMP!$A$11:$A$51)*('Monthly Cost Report'!$C8=RMP!$D$11:$D$51)*(RMP!$BX$10:$CD$10='Monthly Cost Report'!$O$2)*RMP!$BX$11:$CD$51)} -> 7600 | H8: {=+SUMPRODUCT(("Actual"=RMP!$A$11:$A$51)*('Monthly Cost Report'!$C8=RMP!$D$11:$D$51)*(RMP!$AJ$10:$AP$10<='Monthly Cost Report'!$O$2)*RMP!$AJ$11:$AP$51)} -> 504 | I8: {=+SUMPRODUCT(("Actual"=RMP!$A$11:$A$51)*('Monthly Cost Report'!$C8=RMP!$D$11:$D$51)*(RMP!$BX$10:$CD$10<='Monthly Cost Report'!$O$2)*RMP!$BX$11:$CD$51)} -> 25200 | J8: {=+$H8+(SUMPRODUCT(("Forecast"=RMP!$A$11:$A$51)*('Monthly Cost Report'!$C8=RMP!$D$11:$D$51)*(RMP!$AJ$10:$AP$10>'Monthly Cost Report'!$O$2)*RMP!$AJ$11:$AP$51))} -> 804 | K8: {=+$I8+(SUMPRODUCT(("Forecast"=RMP!$A$11:$A$51)*('Monthly Cost Report'!$C8=RMP!$D$11:$D$51)*(RMP!$BX$10:$CD$10>'Monthly Cost Report'!$O$2)*RMP!$BX$11:$CD$51))} -> 40200 | L8: =+J8-H8 -> 300 | M8: =+K8-I8 -> 15000 | N8: =+J8-D8 -> 0 | O8: =+K8-E8 -> 0
