Workbook

Sheet Raw Data
A1: Invoice ID | B1: Invoice Date | C1: Due Date | D1: Vendor ID | E1: Vendor Name | F1: Expense Category | G1: Department | H1: Description | I1: Quantity | J1: Unit Cost | K1: Invoice Amount | L1: Payment Status | M1: Payment Date | N1: Payment Method
A2: INV-0001 | B2: 2025-01-13 | C2: 2025-02-27 | D2: V002 | E2: Tech Solutions Ltd | F2: Software | G2: IT | H2: Business application | I2: 4 | J2: 885.59 | K2: 3542.36 | L2: Paid | M2: 2025-01-21 | N2: UPI
A3: INV-0002 | B3: 2025-01-16 | C3: 2025-01-31 | D3: V001 | E3: ABC Office Supplies | F3: Office Supplies | G3: Administration | H3: Printer paper | I3: 18 | J3: 428 | K3: 7703.99 | L3: Paid | M3: 2025-01-31 | N3: UPI
A4: INV-0003 | B4: 2025-08-18 | C4: 2025-10-02 | D4: V004 | E4: Bright Marketing Co | F4: Marketing | G4: Marketing | H4: Digital advertising | I4: 14 | J4: 933.73 | K4: 13072.18 | L4: Paid | M4: 2025-09-11 | N4: Cheque
A5: INV-0004 | B5: 2025-04-21 | C5: 2025-05-21 | D5: V003 | E5: CleanPro Services | F5: Facilities | G5: Facilities | H5: Maintenance | I5: 12 | J5: 487.83 | K5: 5853.93 | L5: Paid | M5: 2025-05-10 | N5: Bank Transfer
A6: INV-0005 | B6: 2025-10-02 | C6: 2025-10-17 | D6: V008 | E6: CloudWorks Software | F6: Software | G6: IT | H6: Business application | I6: 10 | J6: 583.34 | K6: 5833.38 | L6: Overdue
A7: INV-0006 | B7: 2025-07-05 | C7: 2025-08-19 | D7: V010 | E7: FreshBite Catering | F7: Office Supplies | G7: Administration | H7: Printer cartridges | I7: 8 | J7: 159.49 | K7: 1275.94 | L7: Paid | M7: 2025-07-26 | N7: Bank Transfer
A8: INV-0007 | B8: 2025-02-21 | C8: 2025-03-23 | D8: V004 | E8: Bright Marketing Co | F8: Marketing | G8: Marketing | H8: Printing and promotion | I8: 6 | J8: 1604.39 | K8: 9626.35 | L8: Paid | M8: 2025-03-19 | N8: Cheque
A9: INV-0008 | B9: 2025-12-10 | C9: 2026-01-09 | D9: V004 | E9: Bright Marketing Co | F9: Marketing | G9: Marketing | H9: Digital advertising | I9: 20 | J9: 516.62 | K9: 10332.33 | L9: Pending
A10: INV-0009 | B10: 2025-10-01 | C10: 2025-11-15 | D10: V003 | E10: CleanPro Services | F10: Facilities | G10: Facilities | H10: Maintenance | I10: 18 | J10: 392.69 | K10: 7068.34 | L10: Paid | M10: 2025-10-18 | N10: Cheque
A11: INV-0010 | B11: 2025-04-28 | C11: 2025-05-13 | D11: V001 | E11: ABC Office Supplies | F11: Office Supplies | G11: Administration | H11: Printer paper | I11: 7 | J11: 881.03 | K11: 6167.18 | L11: Pending
A12: INV-0011 | B12: 2025-06-11 | C12: 2025-06-26 | D12: V010 | E12: FreshBite Catering | F12: Office Supplies | G12: Administration | H12: Printer cartridges | I12: 15 | J12: 405.7 | K12: 6085.57 | L12: Pending
A13: INV-0012 | B13: 2025-05-16 | C13: 2025-05-31 | D13: V003 | E13: CleanPro Services | F13: Facilities | G13: Facilities | H13: Maintenance | I13: 19 | J13: 448.96 | K13: 8530.18 | L13: Paid | M13: 2025-06-15 | N13: UPI
A14: INV-0013 | B14: 2025-04-23 | C14: 2025-05-08 | D14: V006 | E14: PeopleFirst HR Services | F14: HR Services | G14: HR | H14: Recruitment service | I14: 4 | J14: 397.73 | K14: 1590.91 | L14: Paid | M14: 2025-05-05 | N14: Credit Card
A15: INV-0014 | B15: 2025-11-02 | C15: 2025-11-17 | D15: V007 | E15: SafeGuard Security | F15: Facilities | G15: Facilities | H15: Maintenance | I15: 17 | J15: 531.73 | K15: 9039.35 | L15: Paid | M15: 2025-11-21 | N15: Bank Transfer
A16: INV-0015 | B16: 2025-12-16 | C16: 2026-01-30 | D16: V002 | E16: Tech Solutions Ltd | F16: Software | G16: IT | H16: Cloud storage | I16: 4 | J16: 2896.71 | K16: 11586.83 | L16: Pending
A17: INV-0016 | B17: 2025-08-11 | C17: 2025-08-26 | D17: V005 | E17: Metro Logistics | F17: Logistics | G17: Operations | H17: Delivery service | I17: 9 | J17: 1590.98 | K17: 14318.78 | L17: Paid | M17: 2025-09-15 | N17: Credit Card
A18: INV-0017 | B18: 2025-02-24 | C18: 2025-04-10 | D18: V009 | E18: Prime Travel Services | F18: Travel | G18: Operations | H18: Travel expenses | I18: 7 | J18: 1382.07 | K18: 9674.51 | L18: Paid | M18: 2025-03-08 | N18: Cheque
A19: INV-0018 | B19: 2025-10-04 | C19: 2025-11-18 | D19: V003 | E19: CleanPro Services | F19: Facilities | G19: Facilities | H19: Maintenance | I19: 1 | J19: 9084.43 | K19: 9084.43 | L19: Overdue
A20: INV-0019 | B20: 2025-07-05 | C20: 2025-08-04 | D20: V002 | E20: Tech Solutions Ltd | F20: Software | G20: IT | H20: Business application | I20: 3 | J20: 1267.62 | K20: 3802.86 | L20: Paid | M20: 2025-07-13 | N20: UPI
A21: INV-0020 | B21: 2025-09-30 | C21: 2025-10-15 | D21: V002 | E21: Tech Solutions Ltd | F21: Software | G21: IT | H21: Business application | I21: 6 | J21: 1210.07 | K21: 7260.42 | L21: Paid | M21: 2025-10-19 | N21: UPI
A22: INV-0021 | B22: 2025-10-04 | C22: 2025-11-18 | D22: V004 | E22: Bright Marketing Co | F22: Marketing | G22: Marketing | H22: Printing and promotion | I22: 12 | J22: 897.17 | K22: 10766 | L22: Pending
A23: INV-0022 | B23: 2025-09-22 | C23: 2025-10-22 | D23: V008 | E23: CloudWorks Software | F23: Software | G23: IT | H23: Cloud storage | I23: 1 | J23: 3564.29 | K23: 3564.29 | L23: Paid | M23: 2025-10-09 | N23: Credit Card
A24: INV-0023 | B24: 2025-02-06 | C24: 2025-03-23 | D24: V001 | E24: ABC Office Supplies | F24: Office Supplies | G24: Administration | H24: Printer paper | I24: 11 | J24: 329.72 | K24: 3626.89 | L24: Pending
A25: INV-0024 | B25: 2025-09-21 | C25: 2025-10-06 | D25: V002 | E25: Tech Solutions Ltd | F25: Software | G25: IT | H25: Business application | I25: 5 | J25: 1481.97 | K25: 7409.86 | L25: Paid | M25: 2025-10-24 | N25: Credit Card
A26: INV-0025 | B26: 2025-07-28 | C26: 2025-08-12 | D26: V008 | E26: CloudWorks Software | F26: Software | G26: IT | H26: Cloud storage | I26: 14 | J26: 712.14 | K26: 9970 | L26: Paid | M26: 2025-08-26 | N26: UPI
A27: INV-0026 | B27: 2025-12-11 | C27: 2026-01-25 | D27: V001 | E27: ABC Office Supplies | F27: Office Supplies | G27: Administration | H27: Pens and stationery | I27: 11 | J27: 154.7 | K27: 1701.66 | L27: Overdue
A28: INV-0027 | B28: 2025-05-08 | C28: 2025-05-23 | D28: V002 | E28: Tech Solutions Ltd | F28: Software | G28: IT | H28: Cloud storage | I28: 6 | J28: 1144.51 | K28: 6867.05 | L28: Paid | M28: 2025-05-28 | N28: UPI
A29: INV-0028 | B29: 2025-02-08 | C29: 2025-03-10 | D29: V004 | E29: Bright Marketing Co | F29: Marketing | G29: Marketing | H29: Digital advertising | I29: 2 | J29: 6437.76 | K29: 12875.51 | L29: Pending
A30: INV-0029 | B30: 2025-01-08 | C30: 2025-01-23 | D30: V009 | E30: Prime Travel Services | F30: Travel | G30: Operations | H30: Flight booking | I30: 14 | J30: 912.02 | K30: 12768.26 | L30: Overdue
A31: INV-0030 | B31: 2025-09-04 | C31: 2025-09-19 | D31: V008 | E31: CloudWorks Software | F31: Software | G31: IT | H31: Software subscription | I31: 13 | J31: 1043.16 | K31: 13561.03 | L31: Overdue
A32: INV-0031 | B32: 2025-07-19 | C32: 2025-08-18 | D32: V001 | E32: ABC Office Supplies | F32: Office Supplies | G32: Administration | H32: Pens and stationery | I32: 14 | J32: 845.05 | K32: 11830.66 | L32: Overdue
A33: INV-0032 | B33: 2025-12-05 | C33: 2026-01-19 | D33: V009 | E33: Prime Travel Services | F33: Travel | G33: Operations | H33: Flight booking | I33: 2 | J33: 1525.49 | K33: 3050.99 | L33: Paid | M33: 2025-12-11 | N33: Cheque
A34: INV-0033 | B34: 2025-01-26 | C34: 2025-03-12 | D34: V001 | E34: ABC Office Supplies | F34: Office Supplies | G34: Administration | H34: Printer cartridges | I34: 6 | J34: 2301.83 | K34: 13810.96 | L34: Paid | M34: 2025-02-01 | N34: Bank Transfer
A35: INV-0034 | B35: 2025-02-05 | C35: 2025-03-22 | D35: V003 | E35: CleanPro Services | F35: Facilities | G35: Facilities | H35: Maintenance | I35: 4 | J35: 3240.46 | K35: 12961.83 | L35: Paid | M35: 2025-02-23 | N35: Bank Transfer
A36: INV-0035 | B36: 2025-02-11 | C36: 2025-03-13 | D36: V010 | E36: FreshBite Catering | F36: Office Supplies | G36: Administration | H36: Pens and stationery | I36: 9 | J36: 954.12 | K36: 8587.1 | L36: Pending
A37: INV-0036 | B37: 2025-12-09 | C37: 2026-01-23 | D37: V004 | E37: Bright Marketing Co | F37: Marketing | G37: Marketing | H37: Digital advertising | I37: 10 | J37: 416.78 | K37: 4167.81 | L37: Paid | M37: 2026-01-10 | N37: Cheque
A38: INV-0037 | B38: 2025-01-05 | C38: 2025-02-04 | D38: V002 | E38: Tech Solutions Ltd | F38: Software | G38: IT | H38: Software subscription | I38: 3 | J38: 2851.39 | K38: 8554.16 | L38: Pending
A39: INV-0038 | B39: 2025-04-20 | C39: 2025-06-04 | D39: V009 | E39: Prime Travel Services | F39: Travel | G39: Operations | H39: Flight booking | I39: 8 | J39: 1751.95 | K39: 14015.58 | L39: Paid | M39: 2025-05-16 | N39: Cheque
A40: INV-0039 | B40: 2025-08-13 | C40: 2025-09-27 | D40: V003 | E40: CleanPro Services | F40: Facilities | G40: Facilities | H40: Security service | I40: 17 | J40: 545.43 | K40: 9272.25 | L40: Pending
...

Sheet Vendor Mapping
A1: Vendor ID | B1: Vendor Name | C1: Department | D1: Vendor Category
A2: V001 | B2: ABC Office Supplies | C2: Administration | D2: Office Supplies
A3: V002 | B3: Tech Solutions Ltd | C3: IT | D3: Software
A4: V003 | B4: CleanPro Services | C4: Facilities | D4: Facilities
A5: V004 | B5: Bright Marketing Co | C5: Marketing | D5: Marketing
A6: V005 | B6: Metro Logistics | C6: Operations | D6: Logistics
A7: V006 | B7: PeopleFirst HR Services | C7: HR | D7: HR Services
A8: V007 | B8: SafeGuard Security | C8: Facilities | D8: Facilities
A9: V008 | B9: CloudWorks Software | C9: IT | D9: Software
A10: V009 | B10: Prime Travel Services | C10: Operations | D10: Travel
A11: V010 | B11: FreshBite Catering | C11: Administration | D11: Office Supplies

Sheet Project Notes
A1: Project | B1: Purpose | C1: Note
A2: Invoice & Expense Analysis Dashboard | B2: Practice data cleaning, XLOOKUP, SUMIFS/COUNTIFS, PivotTables, duplicate detection, vendor/payment analysis, dashboard creation and business insights. | C2: Raw Data contains 83 records including 3 deliberate duplicate invoice records for the duplicate-identification exercise.

Sheet Cleaned Data
A1: Invoice ID | B1: Invoice Date | C1: Due Date | D1: Vendor ID | E1: Vendor Name | F1: Expense Category | G1: Department | H1: Description | I1: Quantity | J1: Unit Cost | K1: Invoice Amount | L1: Payment Status | M1: Payment Date | N1: Payment Method | O1: Lookup Department | P1: Duplicate Check | Q1: Invoice Month
A2: INV-0001 | B2: 2025-01-13 | C2: 2025-02-27 | D2: V002 | E2: Tech Solutions Ltd | F2: Software | G2: IT | H2: Business application | I2: 4 | J2: 885.59 | K2: 3542.36 | L2: Paid | M2: 2025-01-21 | N2: UPI | O2: =XLOOKUP(D2,'Vendor Mapping'!$A:$A,'Vendor Mapping'!$C:$C,"Not Found") | P2: =IF(COUNTIFS($D:$D,D2,$B:$B,B2,$K:$K,K2)>1,"Duplicate","Unique") | Q2: =TEXT(B2,"mmm")
A3: INV-0002 | B3: 2025-01-16 | C3: 2025-01-31 | D3: V001 | E3: ABC Office Supplies | F3: Office Supplies | G3: Administration | H3: Printer paper | I3: 18 | J3: 428 | K3: 7703.99 | L3: Paid | M3: 2025-01-31 | N3: UPI | O3: =XLOOKUP(D3,'Vendor Mapping'!$A:$A,'Vendor Mapping'!$C:$C,"Not Found") | P3: =IF(COUNTIFS($D:$D,D3,$B:$B,B3,$K:$K,K3)>1,"Duplicate","Unique") | Q3: =TEXT(B3,"mmm")
A4: INV-0003 | B4: 2025-08-18 | C4: 2025-10-02 | D4: V004 | E4: Bright Marketing Co | F4: Marketing | G4: Marketing | H4: Digital advertising | I4: 14 | J4: 933.73 | K4: 13072.18 | L4: Paid | M4: 2025-09-11 | N4: Cheque | O4: =XLOOKUP(D4,'Vendor Mapping'!$A:$A,'Vendor Mapping'!$C:$C,"Not Found") | P4: =IF(COUNTIFS($D:$D,D4,$B:$B,B4,$K:$K,K4)>1,"Duplicate","Unique") | Q4: =TEXT(B4,"mmm")
A5: INV-0004 | B5: 2025-04-21 | C5: 2025-05-21 | D5: V003 | E5: CleanPro Services | F5: Facilities | G5: Facilities | H5: Maintenance | I5: 12 | J5: 487.83 | K5: 5853.93 | L5: Paid | M5: 2025-05-10 | N5: Bank Transfer | O5: =XLOOKUP(D5,'Vendor Mapping'!$A:$A,'Vendor Mapping'!$C:$C,"Not Found") | P5: =IF(COUNTIFS($D:$D,D5,$B:$B,B5,$K:$K,K5)>1,"Duplicate","Unique") | Q5: =TEXT(B5,"mmm")
A6: INV-0005 | B6: 2025-10-02 | C6: 2025-10-17 | D6: V008 | E6: CloudWorks Software | F6: Software | G6: IT | H6: Business application | I6: 10 | J6: 583.34 | K6: 5833.38 | L6: Overdue | O6: =XLOOKUP(D6,'Vendor Mapping'!$A:$A,'Vendor Mapping'!$C:$C,"Not Found") | P6: =IF(COUNTIFS($D:$D,D6,$B:$B,B6,$K:$K,K6)>1,"Duplicate","Unique") | Q6: =TEXT(B6,"mmm")
A7: INV-0006 | B7: 2025-07-05 | C7: 2025-08-19 | D7: V010 | E7: FreshBite Catering | F7: Office Supplies | G7: Administration | H7: Printer cartridges | I7: 8 | J7: 159.49 | K7: 1275.94 | L7: Paid | M7: 2025-07-26 | N7: Bank Transfer | O7: =XLOOKUP(D7,'Vendor Mapping'!$A:$A,'Vendor Mapping'!$C:$C,"Not Found") | P7: =IF(COUNTIFS($D:$D,D7,$B:$B,B7,$K:$K,K7)>1,"Duplicate","Unique") | Q7: =TEXT(B7,"mmm")
A8: INV-0007 | B8: 2025-02-21 | C8: 2025-03-23 | D8: V004 | E8: Bright Marketing Co | F8: Marketing | G8: Marketing | H8: Printing and promotion | I8: 6 | J8: 1604.39 | K8: 9626.35 | L8: Paid | M8: 2025-03-19 | N8: Cheque | O8: =XLOOKUP(D8,'Vendor Mapping'!$A:$A,'Vendor Mapping'!$C:$C,"Not Found") | P8: =IF(COUNTIFS($D:$D,D8,$B:$B,B8,$K:$K,K8)>1,"Duplicate","Unique") | Q8: =TEXT(B8,"mmm")
A9: INV-0008 | B9: 2025-12-10 | C9: 2026-01-09 | D9: V004 | E9: Bright Marketing Co | F9: Marketing | G9: Marketing | H9: Digital advertising | I9: 20 | J9: 516.62 | K9: 10332.33 | L9: Pending | O9: =XLOOKUP(D9,'Vendor Mapping'!$A:$A,'Vendor Mapping'!$C:$C,"Not Found") | P9: =IF(COUNTIFS($D:$D,D9,$B:$B,B9,$K:$K,K9)>1,"Duplicate","Unique") | Q9: =TEXT(B9,"mmm")
A10: INV-0009 | B10: 2025-10-01 | C10: 2025-11-15 | D10: V003 | E10: CleanPro Services | F10: Facilities | G10: Facilities | H10: Maintenance | I10: 18 | J10: 392.69 | K10: 7068.34 | L10: Paid | M10: 2025-10-18 | N10: Cheque | O10: =XLOOKUP(D10,'Vendor Mapping'!$A:$A,'Vendor Mapping'!$C:$C,"Not Found") | P10: =IF(COUNTIFS($D:$D,D10,$B:$B,B10,$K:$K,K10)>1,"Duplicate","Unique") | Q10: =TEXT(B10,"mmm")
A11: INV-0010 | B11: 2025-04-28 | C11: 2025-05-13 | D11: V001 | E11: ABC Office Supplies | F11: Office Supplies | G11: Administration | H11: Printer paper | I11: 7 | J11: 881.03 | K11: 6167.18 | L11: Pending | O11: =XLOOKUP(D11,'Vendor Mapping'!$A:$A,'Vendor Mapping'!$C:$C,"Not Found") | P11: =IF(COUNTIFS($D:$D,D11,$B:$B,B11,$K:$K,K11)>1,"Duplicate","Unique") | Q11: =TEXT(B11,"mmm")
A12: INV-0011 | B12: 2025-06-11 | C12: 2025-06-26 | D12: V010 | E12: FreshBite Catering | F12: Office Supplies | G12: Administration | H12: Printer cartridges | I12: 15 | J12: 405.7 | K12: 6085.57 | L12: Pending | O12: =XLOOKUP(D12,'Vendor Mapping'!$A:$A,'Vendor Mapping'!$C:$C,"Not Found") | P12: =IF(COUNTIFS($D:$D,D12,$B:$B,B12,$K:$K,K12)>1,"Duplicate","Unique") | Q12: =TEXT(B12,"mmm")
A13: INV-0012 | B13: 2025-05-16 | C13: 2025-05-31 | D13: V003 | E13: CleanPro Services | F13: Facilities | G13: Facilities | H13: Maintenance | I13: 19 | J13: 448.96 | K13: 8530.18 | L13: Paid | M13: 2025-06-15 | N13: UPI | O13: =XLOOKUP(D13,'Vendor Mapping'!$A:$A,'Vendor Mapping'!$C:$C,"Not Found") | P13: =IF(COUNTIFS($D:$D,D13,$B:$B,B13,$K:$K,K13)>1,"Duplicate","Unique") | Q13: =TEXT(B13,"mmm")
A14: INV-0013 | B14: 2025-04-23 | C14: 2025-05-08 | D14: V006 | E14: PeopleFirst HR Services | F14: HR Services | G14: HR | H14: Recruitment service | I14: 4 | J14: 397.73 | K14: 1590.91 | L14: Paid | M14: 2025-05-05 | N14: Credit Card | O14: =XLOOKUP(D14,'Vendor Mapping'!$A:$A,'Vendor Mapping'!$C:$C,"Not Found") | P14: =IF(COUNTIFS($D:$D,D14,$B:$B,B14,$K:$K,K14)>1,"Duplicate","Unique") | Q14: =TEXT(B14,"mmm")
A15: INV-0014 | B15: 2025-11-02 | C15: 2025-11-17 | D15: V007 | E15: SafeGuard Security | F15: Facilities | G15: Facilities | H15: Maintenance | I15: 17 | J15: 531.73 | K15: 9039.35 | L15: Paid | M15: 2025-11-21 | N15: Bank Transfer | O15: =XLOOKUP(D15,'Vendor Mapping'!$A:$A,'Vendor Mapping'!$C:$C,"Not Found") | P15: =IF(COUNTIFS($D:$D,D15,$B:$B,B15,$K:$K,K15)>1,"Duplicate","Unique") | Q15: =TEXT(B15,"mmm")
A16: INV-0015 | B16: 2025-12-16 | C16: 2026-01-30 | D16: V002 | E16: Tech Solutions Ltd | F16: Software | G16: IT | H16: Cloud storage | I16: 4 | J16: 2896.71 | K16: 11586.83 | L16: Pending | O16: =XLOOKUP(D16,'Vendor Mapping'!$A:$A,'Vendor Mapping'!$C:$C,"Not Found") | P16: =IF(COUNTIFS($D:$D,D16,$B:$B,B16,$K:$K,K16)>1,"Duplicate","Unique") | Q16: =TEXT(B16,"mmm")
A17: INV-0016 | B17: 2025-08-11 | C17: 2025-08-26 | D17: V005 | E17: Metro Logistics | F17: Logistics | G17: Operations | H17: Delivery service | I17: 9 | J17: 1590.98 | K17: 14318.78 | L17: Paid | M17: 2025-09-15 | N17: Credit Card | O17: =XLOOKUP(D17,'Vendor Mapping'!$A:$A,'Vendor Mapping'!$C:$C,"Not Found") | P17: =IF(COUNTIFS($D:$D,D17,$B:$B,B17,$K:$K,K17)>1,"Duplicate","Unique") | Q17: =TEXT(B17,"mmm")
A18: INV-0017 | B18: 2025-02-24 | C18: 2025-04-10 | D18: V009 | E18: Prime Travel Services | F18: Travel | G18: Operations | H18: Travel expenses | I18: 7 | J18: 1382.07 | K18: 9674.51 | L18: Paid | M18: 2025-03-08 | N18: Cheque | O18: =XLOOKUP(D18,'Vendor Mapping'!$A:$A,'Vendor Mapping'!$C:$C,"Not Found") | P18: =IF(COUNTIFS($D:$D,D18,$B:$B,B18,$K:$K,K18)>1,"Duplicate","Unique") | Q18: =TEXT(B18,"mmm")
A19: INV-0018 | B19: 2025-10-04 | C19: 2025-11-18 | D19: V003 | E19: CleanPro Services | F19: Facilities | G19: Facilities | H19: Maintenance | I19: 1 | J19: 9084.43 | K19: 9084.43 | L19: Overdue | O19: =XLOOKUP(D19,'Vendor Mapping'!$A:$A,'Vendor Mapping'!$C:$C,"Not Found") | P19: =IF(COUNTIFS($D:$D,D19,$B:$B,B19,$K:$K,K19)>1,"Duplicate","Unique") | Q19: =TEXT(B19,"mmm")
A20: INV-0019 | B20: 2025-07-05 | C20: 2025-08-04 | D20: V002 | E20: Tech Solutions Ltd | F20: Software | G20: IT | H20: Business application | I20: 3 | J20: 1267.62 | K20: 3802.86 | L20: Paid | M20: 2025-07-13 | N20: UPI | O20: =XLOOKUP(D20,'Vendor Mapping'!$A:$A,'Vendor Mapping'!$C:$C,"Not Found") | P20: =IF(COUNTIFS($D:$D,D20,$B:$B,B20,$K:$K,K20)>1,"Duplicate","Unique") | Q20: =TEXT(B20,"mmm")
A21: INV-0020 | B21: 2025-09-30 | C21: 2025-10-15 | D21: V002 | E21: Tech Solutions Ltd | F21: Software | G21: IT | H21: Business application | I21: 6 | J21: 1210.07 | K21: 7260.42 | L21: Paid | M21: 2025-10-19 | N21: UPI | O21: =XLOOKUP(D21,'Vendor Mapping'!$A:$A,'Vendor Mapping'!$C:$C,"Not Found") | P21: =IF(COUNTIFS($D:$D,D21,$B:$B,B21,$K:$K,K21)>1,"Duplicate","Unique") | Q21: =TEXT(B21,"mmm")
A22: INV-0021 | B22: 2025-10-04 | C22: 2025-11-18 | D22: V004 | E22: Bright Marketing Co | F22: Marketing | G22: Marketing | H22: Printing and promotion | I22: 12 | J22: 897.17 | K22: 10766 | L22: Pending | O22: =XLOOKUP(D22,'Vendor Mapping'!$A:$A,'Vendor Mapping'!$C:$C,"Not Found") | P22: =IF(COUNTIFS($D:$D,D22,$B:$B,B22,$K:$K,K22)>1,"Duplicate","Unique") | Q22: =TEXT(B22,"mmm")
A23: INV-0022 | B23: 2025-09-22 | C23: 2025-10-22 | D23: V008 | E23: CloudWorks Software | F23: Software | G23: IT | H23: Cloud storage | I23: 1 | J23: 3564.29 | K23: 3564.29 | L23: Paid | M23: 2025-10-09 | N23: Credit Card | O23: =XLOOKUP(D23,'Vendor Mapping'!$A:$A,'Vendor Mapping'!$C:$C,"Not Found") | P23: =IF(COUNTIFS($D:$D,D23,$B:$B,B23,$K:$K,K23)>1,"Duplicate","Unique") | Q23: =TEXT(B23,"mmm")
A24: INV-0023 | B24: 2025-02-06 | C24: 2025-03-23 | D24: V001 | E24: ABC Office Supplies | F24: Office Supplies | G24: Administration | H24: Printer paper | I24: 11 | J24: 329.72 | K24: 3626.89 | L24: Pending | O24: =XLOOKUP(D24,'Vendor Mapping'!$A:$A,'Vendor Mapping'!$C:$C,"Not Found") | P24: =IF(COUNTIFS($D:$D,D24,$B:$B,B24,$K:$K,K24)>1,"Duplicate","Unique") | Q24: =TEXT(B24,"mmm")
A25: INV-0024 | B25: 2025-09-21 | C25: 2025-10-06 | D25: V002 | E25: Tech Solutions Ltd | F25: Software | G25: IT | H25: Business application | I25: 5 | J25: 1481.97 | K25: 7409.86 | L25: Paid | M25: 2025-10-24 | N25: Credit Card | O25: =XLOOKUP(D25,'Vendor Mapping'!$A:$A,'Vendor Mapping'!$C:$C,"Not Found") | P25: =IF(COUNTIFS($D:$D,D25,$B:$B,B25,$K:$K,K25)>1,"Duplicate","Unique") | Q25: =TEXT(B25,"mmm")
A26: INV-0025 | B26: 2025-07-28 | C26: 2025-08-12 | D26: V008 | E26: CloudWorks Software | F26: Software | G26: IT | H26: Cloud storage | I26: 14 | J26: 712.14 | K26: 9970 | L26: Paid | M26: 2025-08-26 | N26: UPI | O26: =XLOOKUP(D26,'Vendor Mapping'!$A:$A,'Vendor Mapping'!$C:$C,"Not Found") | P26: =IF(COUNTIFS($D:$D,D26,$B:$B,B26,$K:$K,K26)>1,"Duplicate","Unique") | Q26: =TEXT(B26,"mmm")
A27: INV-0026 | B27: 2025-12-11 | C27: 2026-01-25 | D27: V001 | E27: ABC Office Supplies | F27: Office Supplies | G27: Administration | H27: Pens and stationery | I27: 11 | J27: 154.7 | K27: 1701.66 | L27: Overdue | O27: =XLOOKUP(D27,'Vendor Mapping'!$A:$A,'Vendor Mapping'!$C:$C,"Not Found") | P27: =IF(COUNTIFS($D:$D,D27,$B:$B,B27,$K:$K,K27)>1,"Duplicate","Unique") | Q27: =TEXT(B27,"mmm")
A28: INV-0027 | B28: 2025-05-08 | C28: 2025-05-23 | D28: V002 | E28: Tech Solutions Ltd | F28: Software | G28: IT | H28: Cloud storage | I28: 6 | J28: 1144.51 | K28: 6867.05 | L28: Paid | M28: 2025-05-28 | N28: UPI | O28: =XLOOKUP(D28,'Vendor Mapping'!$A:$A,'Vendor Mapping'!$C:$C,"Not Found") | P28: =IF(COUNTIFS($D:$D,D28,$B:$B,B28,$K:$K,K28)>1,"Duplicate","Unique") | Q28: =TEXT(B28,"mmm")
A29: INV-0028 | B29: 2025-02-08 | C29: 2025-03-10 | D29: V004 | E29: Bright Marketing Co | F29: Marketing | G29: Marketing | H29: Digital advertising | I29: 2 | J29: 6437.76 | K29: 12875.51 | L29: Pending | O29: =XLOOKUP(D29,'Vendor Mapping'!$A:$A,'Vendor Mapping'!$C:$C,"Not Found") | P29: =IF(COUNTIFS($D:$D,D29,$B:$B,B29,$K:$K,K29)>1,"Duplicate","Unique") | Q29: =TEXT(B29,"mmm")
A30: INV-0029 | B30: 2025-01-08 | C30: 2025-01-23 | D30: V009 | E30: Prime Travel Services | F30: Travel | G30: Operations | H30: Flight booking | I30: 14 | J30: 912.02 | K30: 12768.26 | L30: Overdue | O30: =XLOOKUP(D30,'Vendor Mapping'!$A:$A,'Vendor Mapping'!$C:$C,"Not Found") | P30: =IF(COUNTIFS($D:$D,D30,$B:$B,B30,$K:$K,K30)>1,"Duplicate","Unique") | Q30: =TEXT(B30,"mmm")
A31: INV-0030 | B31: 2025-09-04 | C31: 2025-09-19 | D31: V008 | E31: CloudWorks Software | F31: Software | G31: IT | H31: Software subscription | I31: 13 | J31: 1043.16 | K31: 13561.03 | L31: Overdue | O31: =XLOOKUP(D31,'Vendor Mapping'!$A:$A,'Vendor Mapping'!$C:$C,"Not Found") | P31: =IF(COUNTIFS($D:$D,D31,$B:$B,B31,$K:$K,K31)>1,"Duplicate","Unique") | Q31: =TEXT(B31,"mmm")
A32: INV-0031 | B32: 2025-07-19 | C32: 2025-08-18 | D32: V001 | E32: ABC Office Supplies | F32: Office Supplies | G32: Administration | H32: Pens and stationery | I32: 14 | J32: 845.05 | K32: 11830.66 | L32: Overdue | O32: =XLOOKUP(D32,'Vendor Mapping'!$A:$A,'Vendor Mapping'!$C:$C,"Not Found") | P32: =IF(COUNTIFS($D:$D,D32,$B:$B,B32,$K:$K,K32)>1,"Duplicate","Unique") | Q32: =TEXT(B32,"mmm")
A33: INV-0032 | B33: 2025-12-05 | C33: 2026-01-19 | D33: V009 | E33: Prime Travel Services | F33: Travel | G33: Operations | H33: Flight booking | I33: 2 | J33: 1525.49 | K33: 3050.99 | L33: Paid | M33: 2025-12-11 | N33: Cheque | O33: =XLOOKUP(D33,'Vendor Mapping'!$A:$A,'Vendor Mapping'!$C:$C,"Not Found") | P33: =IF(COUNTIFS($D:$D,D33,$B:$B,B33,$K:$K,K33)>1,"Duplicate","Unique") | Q33: =TEXT(B33,"mmm")
A34: INV-0033 | B34: 2025-01-26 | C34: 2025-03-12 | D34: V001 | E34: ABC Office Supplies | F34: Office Supplies | G34: Administration | H34: Printer cartridges | I34: 6 | J34: 2301.83 | K34: 13810.96 | L34: Paid | M34: 2025-02-01 | N34: Bank Transfer | O34: =XLOOKUP(D34,'Vendor Mapping'!$A:$A,'Vendor Mapping'!$C:$C,"Not Found") | P34: =IF(COUNTIFS($D:$D,D34,$B:$B,B34,$K:$K,K34)>1,"Duplicate","Unique") | Q34: =TEXT(B34,"mmm")
A35: INV-0034 | B35: 2025-02-05 | C35: 2025-03-22 | D35: V003 | E35: CleanPro Services | F35: Facilities | G35: Facilities | H35: Maintenance | I35: 4 | J35: 3240.46 | K35: 12961.83 | L35: Paid | M35: 2025-02-23 | N35: Bank Transfer | O35: =XLOOKUP(D35,'Vendor Mapping'!$A:$A,'Vendor Mapping'!$C:$C,"Not Found") | P35: =IF(COUNTIFS($D:$D,D35,$B:$B,B35,$K:$K,K35)>1,"Duplicate","Unique") | Q35: =TEXT(B35,"mmm")
A36: INV-0035 | B36: 2025-02-11 | C36: 2025-03-13 | D36: V010 | E36: FreshBite Catering | F36: Office Supplies | G36: Administration | H36: Pens and stationery | I36: 9 | J36: 954.12 | K36: 8587.1 | L36: Pending | O36: =XLOOKUP(D36,'Vendor Mapping'!$A:$A,'Vendor Mapping'!$C:$C,"Not Found") | P36: =IF(COUNTIFS($D:$D,D36,$B:$B,B36,$K:$K,K36)>1,"Duplicate","Unique") | Q36: =TEXT(B36,"mmm")
A37: INV-0036 | B37: 2025-12-09 | C37: 2026-01-23 | D37: V004 | E37: Bright Marketing Co | F37: Marketing | G37: Marketing | H37: Digital advertising | I37: 10 | J37: 416.78 | K37: 4167.81 | L37: Paid | M37: 2026-01-10 | N37: Cheque | O37: =XLOOKUP(D37,'Vendor Mapping'!$A:$A,'Vendor Mapping'!$C:$C,"Not Found") | P37: =IF(COUNTIFS($D:$D,D37,$B:$B,B37,$K:$K,K37)>1,"Duplicate","Unique") | Q37: =TEXT(B37,"mmm")
A38: INV-0037 | B38: 2025-01-05 | C38: 2025-02-04 | D38: V002 | E38: Tech Solutions Ltd | F38: Software | G38: IT | H38: Software subscription | I38: 3 | J38: 2851.39 | K38: 8554.16 | L38: Pending | O38: =XLOOKUP(D38,'Vendor Mapping'!$A:$A,'Vendor Mapping'!$C:$C,"Not Found") | P38: =IF(COUNTIFS($D:$D,D38,$B:$B,B38,$K:$K,K38)>1,"Duplicate","Unique") | Q38: =TEXT(B38,"mmm")
A39: INV-0038 | B39: 2025-04-20 | C39: 2025-06-04 | D39: V009 | E39: Prime Travel Services | F39: Travel | G39: Operations | H39: Flight booking | I39: 8 | J39: 1751.95 | K39: 14015.58 | L39: Paid | M39: 2025-05-16 | N39: Cheque | O39: =XLOOKUP(D39,'Vendor Mapping'!$A:$A,'Vendor Mapping'!$C:$C,"Not Found") | P39: =IF(COUNTIFS($D:$D,D39,$B:$B,B39,$K:$K,K39)>1,"Duplicate","Unique") | Q39: =TEXT(B39,"mmm")
A40: INV-0039 | B40: 2025-08-13 | C40: 2025-09-27 | D40: V003 | E40: CleanPro Services | F40: Facilities | G40: Facilities | H40: Security service | I40: 17 | J40: 545.43 | K40: 9272.25 | L40: Pending | O40: =XLOOKUP(D40,'Vendor Mapping'!$A:$A,'Vendor Mapping'!$C:$C,"Not Found") | P40: =IF(COUNTIFS($D:$D,D40,$B:$B,B40,$K:$K,K40)>1,"Duplicate","Unique") | Q40: =TEXT(B40,"mmm")
...

Sheet Analysis
A1: Metric | B1: Value | D1: Expense Category | E1: Total Expense | G1: Vendor | H1: Total Expense | J1: Payment Status | K1: Invoice Count | L1: Amount | N1: Month | O1: Expense
A2: Total Expenses | B2: 644365.57 | D2: Facilities | E2: 161792.97 | G2: Bright Marketing Co | H2: 105967.49 | J2: Paid | K2: 52 | L2: 396411.13 | N2: Jan | O2: 73567.52
A3: Total Invoices | B3: 83 | D3: Software | E3: 123547.51 | G3: CleanPro Services | H3: 93065.03 | J3: Pending | K3: 22 | L3: 176934.52 | N3: Feb | O3: 78904.35
A4: Paid Amount | B4: 396411.13 | D4: Marketing | E4: 105967.49 | G4: Prime Travel Services | H4: 77275.69 | J4: Overdue | K4: 9 | L4: 71019.92 | N4: Mar | O4: 27985.62
A5: Pending Amount | B5: 176934.52 | D5: Office Supplies | E5: 97504.9 | G5: Tech Solutions Ltd | H5: 73046.67 | N5: Apr | O5: 46768.99
A6: Overdue Amount | B6: 71019.92 | D6: Travel | E6: 77275.69 | G6: SafeGuard Security | H6: 68727.94 | N6: May | O6: 43716.71
A7: Duplicate Invoice Records | B7: 3 | D7: Logistics | E7: 60766.47 | G7: ABC Office Supplies | H7: 66986.94 | N7: Jun | O7: 53668.66
D8: HR Services | E8: 17510.54 | G8: Metro Logistics | H8: 60766.47 | N8: Jul | O8: 41344.55
G9: CloudWorks Software | H9: 50500.84 | N9: Aug | O9: 49734.49
G10: FreshBite Catering | H10: 30517.96 | N10: Sep | O10: 65379.01
G11: PeopleFirst HR Services | H11: 17510.54 | N11: Oct | O11: 65646.05
N12: Nov | O12: 35485.76
N13: Dec | O13: 62163.86

Sheet Dashboard
A1: INVOICE & EXPENSE ANALYSIS DASHBOARD
A2: Microsoft Excel | 2025 Invoice & Expense Analysis
A4: Total Expenses | D4: Total Invoices | G4: Paid Amount | J4: Pending Amount | M4: Overdue Amount
A5: 644365.57 | D5: 83 | G5: 396411.13 | J5: 176934.52 | M5: 71019.92

Sheet Insights
A1: Business Insights
A2: 1. Highest-spend category: Facilities (161,792.97).
A3: 2. Highest-spend vendor: Bright Marketing Co (105,967.49).
A4: 3. Paid invoices account for 396,411.13; pending and overdue amounts should be prioritized.
A5: 4. Duplicate-check logic is included in Cleaned Data to flag repeated invoice combinations.
